Workbook

Sheet 프로세스
A1: 프로젝트 수행 프로세스
B2: 액티비티 | C2: 시점 | D2: 결재라인 | E2: 비고 | F2: 첨부자료
A3: [ 사전영업지원 ]
B4: ■ 영업지원요청 | C4: 기술본부 인력지원필요시 | D4: □ 영업대표->사업본부장->PMO그룹장->기술본부장 | E4: □ 기술인력지원요청서 양식사용
A6: [ 제안 ]
B7: ■ 제안팀 구성 및 발령 요청 | C7: RFP 수령 전/후 | D7: □ 사업본부장 전결(웹메일) ▷참조 : 경영관리부장, 제안팀원 | E7: □ PMO그룹장, 기술본부장, 대표이사 사전 협의 □ 프로젝트 수행 직원 : PM사전협의
B8: ■ 제안팀 발령 | C8: 발령요청 시 | D8: □ 경영관리부장 -> 기술본부장 ▷참조 : PMO그룹장, 사업본부장 | E8: □ 게시판 공지 ▷ 사내게시판 : 인사(프로젝트팀)
B9: ■ 협력업체 인력 구성
B10: ▶사업본부장 확정 | D10: □ 사업본부장 전결 | F10: ⊙ 견적서(초안) : 협력업체 용역, 상품 ⊙ 인력 Profile
B11: ▶ 인력수배 요청 | C11: RFP 수령 전/후 | D11: □ 요청 : 사업본부장 -> 기술본부장(웹메일) | F11: ⊙ 인력요청서
B12: ▶ 인력수배 확정 | C12: 인력수배 요청 후 | D12: □ 제공 : 기술본부장 ->사업본부장(웹메일) | F12: ⊙ 견적서(초안) : 협력업체 용역, 상품 ⊙ 인력 Profile
B13: ■ 제안심사 소위
B14: ▶ 팀원 구성 ▶ 수지차 확정 | C14: 제안서 제출전 | D14: □ 영업대표 발의(업무연락 공지) | E14: □ 참석자: PM, PMO그룹장, 기술본부장,경영관리본부 □ 제안여부, 제안금액 결정 | F14: ⊙ RFP, 제안서 ⊙ 견적서 ⊙ 수지표
A16: [ 계약 ]
B17: ■ 계약내용검토 | C17: 계약 전 | D17: □ 영업대표/PM 발의 | E17: □ 참석자: PM, PMO그룹장, 기술본부장,경영관리본부 □ 계약여부, 계약금액 최종결정 | F17: ⊙ 계약서 초안 ⊙ 내역서(과업지시서 or SOW) 초안 ⊙ 기술협상서 ⊙ 수지표(협상결과에 따른 조정)
A19: [ 프로젝트 수주 품의 ]
B20: ■ 수주 품의 | C20: 계약 직후 | D20: □ 영업대표->(합의)->사업본부장->경영관리부장->대표이사 ▷합의 : PM, PMO그룹장, 기술본부장 | F20: ⊙ 계약서 ⊙ 내역서(과업지시서 or SOW) ⊙ 기술협상서 ⊙ 수지표 : 확정분
A22: [ 프로젝트 사전 준비 ]
B23: ■ 팀원 워크샵 | C23: 프로젝트 착수 전 | D23: □ PM 전결(웹메일) | E23: □ 당사 직원 및 협력업체 참여 가능 □ 예산 : 사전승인 원칙 □ 경비정산 : 프로젝트 수행경비로 계산 | F23: ⊙ 회식/접대비 사전승인 신청서
B24: ■ 제안서 숙지 | C24: 프로젝트 착수 전 | D24: □ 없음 : PM 및 팀원 | E24: □ 제안범위 □ Site별 방법론 등
B25: ■ 수지차 공유 | C25: 프로젝트 착수 전 | D25: □ 없음 : PM 및 사업본부장 | E25: □ 프로세스 숙지 □ 인력계획 □ 경비예산 등
B26: ■ WBS | C26: 프로젝트 착수 전 | D26: □ 없음 : PM 및 팀원 | E26: □ 일정 : 단계-타스크- 액티비티-산출물 □ 산출물 Template : Site별-업무별 Template □ R&R 정의
B27: ■ SOW | C27: 프로젝트 착수 전 | D27: □ 없음 : PM 및 팀원 | E27: □ Site별 Template에 맞는 SOW
B28: ■ 품질보증계획서 | C28: 프로젝트 착수 전 | D28: □ 없음 : PM 및 팀원 | E28: □ Site별 Template에 맞는 품질보증계획서
B29: ■ 프로젝트 수행계획서 | C29: 프로젝트 착수 전 | D29: □ 없음 : PM 및 팀원 | E29: □ Site별 Template에 맞는 수행계획서
B30: ■ 프로젝트 관리용 시스템 | C30: 프로젝트 착수 전 | D30: □ 없음 : PM 및 팀원 | E30: □ 장비 : 서버, 프린터, 빔프로젝터 등
B31: ■ 각종 증명서 | C31: 프로젝트 착수 전 | D31: □ 없음 : PM 및 팀원 | E31: □ Site별 사전 조사 필요 ▷ 재직증명서 ▷ 기술경력증명서 ▷ 신원보증서 ▷ 출입증 발급서류 등
A33: [ 변경 요청 ]
B34: ■ 변경 요청 | C34: 손익 변경 예상시 | D34: □ PM->PMO그룹장->기술본부장->대표이사 ▷합의: (사업본부장),경영관리부장 | F34: ⊙ 수지표(대비)
A36: [ 당사인력 투입 ]
B37: ■ 제안시점 확정
B38: ▶ 요청 | C38: 투입예정 1주일 전 | D38: □ PM -> 사업본부장 -> 기술본부장 -> 대표이사 ▷협의 : PMO그룹장 ▷참조 : 경영관리부장 | F38: ⊙ 수지표 : 인력계획-투입구분 = 투입(정상)
B39: ▶ 발령 | C39: 요청 후 | D39: □ 경영관리부장 -> 기술본부장 -> 대표이사 ▷협의 : PMO그룹장, 사업본부장 | E39: □ 게시판 공지 ▷ 사내게시판 : 인사(프로젝트팀)
B40: ■ 변경/추가 투입
B41: ▶ 요청 | C41: 요건발생 즉시 | D41: □ PM -> 사업본부장 -> 기술본부장 -> 대표이사 ▷협의 : PMO그룹장 ▷참조 : 경영관리부장 | E41: □ 변경/추가투입 인력에 대한 사전 협의 필요 ▷요청 : PM, 사업본부장 ▷협의 : PMO그룹장, 기술본부장, 대표이사 | F41: ⊙ 수지표 : 인력계획-투입구분 = 투입(*)
B42: ▶ 발령 | C42: 요청 후 | D42: □ 경영관리부장 -> 기술본부장 -> 대표이사 ▷협의 : PM, 사업본부장 | E42: □ 게시판 공지 ▷ 사내게시판 : 인사(프로젝트팀)
A44: [ 외주인력 투입 ]
B45: ■ 인력 수배(수주품의시 미확정/변경 인력)
B46: ▶ 인력수배 요청 | C46: 투입예정 2개월 전 | D46: □ PM 전결(웹메일) 단, PM 투입전에는 사업본부장이 요청 | E46: □ 기술본부에 인력수배 요청 ▷ From : PM =>To 기술본부장 | F46: ⊙ 수지표 : 인력계획-투입구분 = 인력수배
B47: ▶ 인력수배 | C47: 인력수배 요청 시 | D47: □ 기술본부장 전결(웹메일) | E47: □ 협력업체에 해당인력 수배 ▷ From : 인력공급본부장 =>To 협력업체 | F47: ⊙ 인력요청서
...

Sheet 수주품의
A1: 프로젝트 수주 품의
H3: 결재 | I3: 영업대표/PM | J3: 그룹장 | K3: 미래전략본부장 | L3: 기술혁신본부장 | M3: 대표이사
H5: 협조 | I5: 경영지원실
A8: [ 프로젝트 개요 ]
B9: 고객명 | C9: 한국남동발전㈜ | H9: 계약형태 | I9: 주계약 | J9: 주사업자 | K9: (주)위엠비
B10: 프로젝트명 | C10: KOEN 스마트 도면관리시스템 구축 용역 | H10: 계약유형 | I10: SI | J10: 기타
B11: PM명 | C11: 정현우 이사 | E11: 기간 | F11: 2024-11-14 ~ 2025-09-13 | H11: 수행장소 | I11: 본사, 진주, 분당
B12: 개요 | C12: ■ 신규 도면관리시스템 구축 ■ 도면의 Life Cycle 시스템화 구현 ■ 모바일 플랫폼 구현 ■ 도면관리 편의기능 구현
B13: 특이사항 | C13: ■ P&ID, SLD 7,000장 이상 ■ PDF, DWG, VISIO 파일 연계 (R&D 지원 필요), R&D 지원이 불가한 경우 도면 작성 인력 투입 대량 증가
B14: Risk | C14: ■ 외주(아르바이트) 인력 관리
A16: [ 수지표 요약 ] | D16: * 자동 작성됨
B17: 용역 | C17: 구분 | D17: M/M | E17: 기준가 | F17: 제안가 | G17: 내부원가 | H17: 지연비용 | I17: 특별경비 | J17: 일반경비 | K17: 경상비용 | L17: 수익률 | M17: 손익
C18: 위엠비 | D18: =인력계획!AG34 -> 32.25 | F18: =인력계획!AK34 -> 685300 | G18: =인력계획!AM34 -> 392678.5 | H18: =수지차!E12 -> 0 | I18: =수지차!E18 -> 40000 | J18: =수지차!E17 -> 1381.25 | K18: =수지차!E28 -> 0 | L18: =IF(F18=0,"0.00%",M18/F18) -> 0.36661353 | M18: =F18-G18-H18-I18-J18-K18 -> 251240.25
C19: 외주 | D19: =인력계획!AG45 -> 23 | F19: =인력계획!AK45 -> 0 | G19: =인력계획!AM45 -> 117980 | H19: =수지차!E15 -> 0 | L19: =IF(F19=0,"0.00%",M19/F19) -> 0.00% | M19: =F19-G19-H19-I19 -> -117980
C20: 소계 | D20: =SUM(D18:D19) -> 55.25 | F20: =SUM(F18:F19) -> 685300 | G20: =SUM(G18:G19) -> 510658.5 | H20: =SUM(H18:H19) -> 0 | I20: =SUM(I18:I19) -> 40000 | J20: =SUM(J18:J19) -> 1381.25 | K20: =SUM(K18:K19) -> 0 | L20: =M20/F20 -> 0.19445535 | M20: =SUM(M18:M19) -> 133260.25
B21: 제품/상품 | C21: 구분 | E21: 기준가 | F21: 제안가 | G21: 원가 | L21: 수익률 | M21: 손익
C22: 위엠비 | F22: =제품계획!H17 -> 0 | G22: =제품계획!J17 -> 0 | L22: =IF(F22=0,"0.00%",M22/F22) -> 0.00% | M22: =F22-G22 -> 0
C23: 외주 | F23: =제품계획!H23 -> 0 | G23: =제품계획!J23 -> 4000 | L23: =IF(F23=0,"0.00%",M23/F23) -> 0.00% | M23: =F23-G23 -> -4000
C24: 소계 | F24: =SUM(F22:F23) -> 0 | G24: =SUM(G22:G23) -> 4000 | L24: 0 | M24: =SUM(M22:M23) -> -4000
B25: 합계 | F25: =SUM(F20,F24) -> 685300 | G25: =SUM(G20,G24) -> 514658.5 | L25: =M25/F25 -> 0.18861849 | M25: =SUM(M20,M24) -> 129260.25
A27: [ 대금 조건 ]
B28: 구분 | D28: 선급금 | G28: 중도금 | K28: 잔금
B29: 용역 | C29: 비율(%) | D29: 0.9 | K29: 0.1
C30: 시기 | D30: 2024.11.26일 계산서 발행 | K30: 2025.09월 중순 이후 예정
B31: 제품/상품 | C31: 비율(%)
C32: 시기
A34: [ 협력 업체 ]
B35: 업체명 | D35: 역할 | G35: 담당자 | I35: 연락처 | K35: 비고
A39: [ 영업 이력 ]
B40: 구분 | C40: 수령일 | D40: 작성 시작일 | E40: 작성 종료일 | F40: 제출일 | G40: 발표일 | H40: PM | I40: 발표자 | J40: 팀원

Sheet 제품계획
A1: [ 제품/상품 계획 ] | M1: [ 제품/상품 발주 의뢰 ]
J2: (단위:천원)
B3: 구분 | C3: 업체명 | D3: 제품명 | E3: 매출 | J3: 매입 | M3: 구매 계약
E4: 수량 | F4: 단가 | G4: 기준가 | H4: 제안가 | I4: 할인률 | J4: 원가 | K4: 당사마진 | L4: 마진율 | M4: 요청일 | N4: 요청구분 | O4: 원가 | P4: 당사마진 | Q4: 마진율
B5: 제품 (자사)
C17: 소계 | F17: =IF(E17>0,G17/E17,0) -> 0 | G17: =SUM(G5:G16) -> 0 | H17: =SUM(H5:H16) -> 0 | I17: =IFERROR((G17-H17)/G17,"") | J17: =SUM(J5:J16) -> 0 | K17: =SUM(K5:K16) -> 0 | L17: =K17/$H17 -> #DIV/0! | O17: =SUM(O5:O16) -> 0 | P17: =SUM(P5:P16) -> 0 | Q17: =P17/$H17 -> #DIV/0!
B18: 상품 (타사) | C18: AJ네트웍스 | D18: 노트북,모니터, 사무가구 등 렌탈 | J18: 4000
G22: =IF(ISBLANK(E22),"",E22*F22) | I22: =IF(ISBLANK(H22),"",(G22-H22)/G22) | K22: =IF(H22-J22=0,"",H22-J22) | L22: =IFERROR(K22/$H22,"") | P22: =IF(O22="","",H22-O22) | Q22: =IFERROR(P22/$H22,"")
C23: 소계 | E23: =SUM(E18:E22) -> 0 | F23: =IF(E23>0,G23/E23,0) -> 0 | G23: =SUM(G18:G22) -> 0 | H23: =SUM(H18:H22) -> 0 | I23: =IFERROR((G23-H23)/G23,"") | J23: =SUM(J18:J22) -> 4000 | K23: =SUM(K18:K22) -> 0 | L23: =K23/$H23 -> #DIV/0! | O23: =SUM(O18:O22) -> 0 | P23: =SUM(P18:P22) -> 0 | Q23: =P23/$H23 -> #DIV/0!
B24: 합계 | E24: =SUM(E23,E17) -> 0 | F24: =IF(E24>0,G24/E24,0) -> 0 | G24: =SUM(G17,G23) -> 0 | H24: =SUM(H23,H17) -> 0 | I24: =IFERROR((G24-H24)/G24,"") | J24: =SUM(J23,J17) -> 4000 | K24: =SUM(K23,K17) -> 0 | L24: =K24/H24 -> #DIV/0! | O24: =SUM(O23,O17) -> 0 | P24: =SUM(P23,P17) -> 0 | Q24: =P24/$H24 -> #DIV/0!
M25: 차액(제안-계약) | O25: =O24-J24 -> -4000 | P25: =P24-K24 -> 0

Sheet 수지차
A1: =수주품의!C10 -> KOEN 스마트 도면관리시스템 구축 용역
A3: 구 분 | E3: 금액 | F3: 지표 | G3: 금액 설명 | H3: 지표 설명 | I3: **색 표시란만 조정하세요!
A4: 프 로 젝 트 | B4: 수주 | C4: 용역 | D4: 당사 | E4: =인력계획!AK33 -> 685300 | G4: 당사계약금액, 부가세 제외 | H4: 당사 평균 단가
D5: 외주 | E5: =인력계획!AK45 -> 0 | G5: 당사계약금액, 부가세 제외 | H5: 외주 평균 단가
D6: 용역소계 | E6: =E4+E5 -> 685300 | H6: 평균단가
C7: 제품 | D7: 당사제품 | E7: =제품계획!H17 -> 0 | G7: 당사계약금액, 부가세 제외
D8: 타사상품 | E8: =제품계획!H23 -> 0 | G8: 타사계약금액, 부가세 제외
D9: 제품소계 | E9: =SUM(E7:E8) -> 0
C10: 수주 합계 | E10: =E6+E9 -> 685300 | F10: =E10*1.1 -> 753830 | H10: 부가가치세 제외된 가격
B11: 용역 손익 | C11: 당사 | D11: 당사 원가 (-) | E11: =인력계획!AM34 -> 392678.5 | H11: 당사 평균 원가(내부가격)
D12: 지연 비용 | E12: =E11*F12 -> 0 | H12: SM 계약인 경우에는 0%, 기타는 10% 적용
D13: 손익 소계 | E13: =E4-E11-E12 -> 292621.5 | F13: =IF(E4=0,"-",E13/E4) -> 0.42699767
C14: 외주 | D14: 외주 원가 (-) | E14: =인력계획!AM45 -> 117980 | H14: 외주 평균 조달 원가
D15: 지연 비용 | E15: =E14*F15 -> 0 | H15: SM 계약인 경우에는 0%, 기타는 10% 적용
D16: 손익 소계 | E16: =E5-E14-E15 -> -117980 | F16: =IF(E16>0,E16/E5,0) -> 0
C17: Project 경비 | D17: 일반 경비 | E17: =프로젝트경비!C10 -> 1381.25 | F17: =E17/E6 -> 0.0020155406
D18: 특별 경비 | E18: =프로젝트경비!C17 -> 40000 | F18: =E18/E6 -> 0.058368598 | G18: Wokshop비용, 임차비, 교통비 등
D19: 경비 소계 | E19: =SUM(E17:E18) -> 41381.25 | F19: =E19/E10 -> 0.060384138
C20: 용역 손익 합계 | E20: =E13+E16-E19 -> 133260.25 | F20: =E20/E10 -> 0.19445535 | H20: 용역 손익 / 용역 수주 합계
B21: 제품 손익 | C21: 당사 | D21: 제품 원가 | E21: =제품계획!J17 -> 0 | F21: =IF(E21>0,E21/E7,0) -> 0 | H21: 제품원가 비율
D22: 손익 소계 | E22: =E7-E21 -> 0 | F22: =IF(E7>0,E22/E7,0) -> 0 | H22: 당사제품 손익 / 당사제품 수주금액
C23: 타사 | D23: 상품 원가 | E23: =제품계획!J23 -> 4000 | F23: =IF(E23>0,E23/E8,0) -> #DIV/0! | H23: 제품원가 비율
D24: 손익 소계 | E24: =E8-E23 -> -4000 | F24: =IF(E8>0,E24/E8,0) -> 0 | H24: 타사상품 손익 / 타사상품 수주금액
C25: 제품 손익 합계 | E25: =SUM(E22,E24) -> -4000 | F25: =IF(E9>0,E25/E9,0) -> 0 | H25: 제품손익/ 제품수주금액
B26: 프로젝트 손익 합계 | E26: =E20+E25 -> 129260.25 | F26: =E26/E10 -> 0.18861849 | H26: 수주합계 / 프로젝트 수익
A27: 손익합계 | B27: 사업 손익 | C27: 당사 제품 원가 (+) | E27: =E21 -> 0 | F27: =IF(E7>0,E27/E7,0) -> 0 | H27: 제품원가 비율
C28: 경상비용 | E28: =E10*F28 -> 0 | H28: 매출액 18%
C29: 사업 손익 합계 | E29: =E26-E28 -> 129260.25 | F29: =E29/E10 -> 0.18861849 | H29: 사업손익 / 수주합계
B30: 부가 수익 | C30: 부가 예상 수익 (+) | E30: 0
C31: 부가 예상 비용 (-) | E31: 0 | G31: SM 등 후속사업 예상 비용
C32: 부가 수익 합계 | E32: =E30-E31 -> 0
B33: 회사 손익 합계 | E33: =E29+E32 -> 129260.25 | F33: =E33/E10 -> 0.18861849 | H33: 회사수익합계 / 수주합계

Sheet 인력계획
A1: [ 인 력 계 획 ] | I1: **색 표시란만 조정하세요!
J2: 비상주 | M2: 외주
A3: 업무영역 | B3: 역할 | C3: 세부업무 | D3: 회사명 | E3: 소속 및 직군 | F3: 위엠비 직급 | G3: 등급 | H3: 성명 | I3: 당년(2024년) | U3: 차년(2025년) | AG3: 총투입 MM
I4: 1월 | J4: 2월 | K4: 3월 | L4: 4월 | M4: 5월 | N4: 6월 | O4: 7월 | P4: 8월 | Q4: 9월 | R4: 10월 | S4: 11월 | T4: 12월 | U4: 1월 | V4: 2월 | W4: 3월 | X4: 4월 | Y4: 5월 | Z4: 6월 | AA4: 7월 | AB4: 8월 | AC4: 9월 | AD4: 10월 | AE4: 11월 | AF4: 12월 | AG4: 합계 | AH4: 당년 | AI4: 차년 | AJ4: 제안가 | AL4: 내부단가
AJ5: 단가 | AK5: 금액 | AL5: 단가 | AM5: 금액
A6: =수주품의!C10 -> KOEN 스마트 도면관리시스템 구축 용역 | B6: PM | C6: 사업관리 | D6: (주)위엠비 | E6: 위엠비_개발 | F6: 이사 | G6: 개_고 | H6: 정현우 | S6: 0.25 | T6: 1 | U6: 1 | V6: 1 | W6: 1 | X6: 1 | Y6: 1 | Z6: 1 | AA6: 1 | AB6: 1 | AC6: 0.5 | AG6: =SUM(I6:AF6) -> 9.75 | AH6: =SUM(I6:T6) -> 1.25 | AI6: =SUM(U6:AF6) -> 8.5 | AJ6: 685300 | AK6: 685300 | AL6: =IF($E6="위엠비_컨설팅",SUMPRODUCT(($F6='기준-단가'!$C$5:$C$11)*('기준-단가'!$H$5:$H$11)), IF($E6="위엠비_개발",SUMPRODUCT(($F6='기준-단가'!$C$13:$C$19)*('기준-단가'!$H$13:$H$19)), IF($E6="외주_컨설팅",SUMPRODUCT(($G6='기준-단가'!$D$21:$D$24)*('기준-단가'!$H$21:$H$24)), IF($E6="외주_개발",SUMPRODUCT(($G6='기준-단가'!$D$26:$D$29)*('기준-단가'!$H$26:$H$29)))))) -> 14616 | AM6: =AG6*AL6 -> 142506
B7: 개발 | C7: 인터페이스 | D7: (주)위엠비 | E7: 위엠비_개발 | F7: 수석(S) | G7: 개_고 | H7: 최진희 | T7: 1 | U7: 1 | V7: 1 | W7: 1 | X7: 1 | Y7: 1 | Z7: 1 | AA7: 1 | AB7: 1 | AC7: 0.5 | AG7: =SUM(I7:AF7) -> 9.5 | AH7: =SUM(I7:T7) -> 1 | AI7: =SUM(U7:AF7) -> 8.5 | AJ7: 0 | AK7: =AG7*AJ7 -> 0 | AL7: =IF($E7="위엠비_컨설팅",SUMPRODUCT(($F7='기준-단가'!$C$5:$C$11)*('기준-단가'!$H$5:$H$11)), IF($E7="위엠비_개발",SUMPRODUCT(($F7='기준-단가'!$C$13:$C$19)*('기준-단가'!$H$13:$H$19)), IF($E7="외주_컨설팅",SUMPRODUCT(($G7='기준-단가'!$D$21:$D$24)*('기준-단가'!$H$21:$H$24)), IF($E7="외주_개발",SUMPRODUCT(($G7='기준-단가'!$D$26:$D$29)*('기준-단가'!$H$26:$H$29)))))) -> 11516 | AM7: =AG7*AL7 -> 109402
B8: 개발 | C8: UI 개발 | D8: (주)위엠비 | E8: 위엠비_개발 | F8: 책임(M) | G8: 개_중 | H8: 이재형 | T8: 1 | U8: 1 | V8: 1 | W8: 1 | X8: 1 | Y8: 1 | Z8: 1 | AA8: 1 | AB8: 1 | AC8: 0.5 | AG8: =SUM(I8:AF8) -> 9.5 | AH8: =SUM(I8:T8) -> 1 | AI8: =SUM(U8:AF8) -> 8.5 | AJ8: 0 | AK8: =AG8*AJ8 -> 0 | AL8: =IF($E8="위엠비_컨설팅",SUMPRODUCT(($F8='기준-단가'!$C$5:$C$11)*('기준-단가'!$H$5:$H$11)), IF($E8="위엠비_개발",SUMPRODUCT(($F8='기준-단가'!$C$13:$C$19)*('기준-단가'!$H$13:$H$19)), IF($E8="외주_컨설팅",SUMPRODUCT(($G8='기준-단가'!$D$21:$D$24)*('기준-단가'!$H$21:$H$24)), IF($E8="외주_개발",SUMPRODUCT(($G8='기준-단가'!$D$26:$D$29)*('기준-단가'!$H$26:$H$29)))))) -> 10641 | AM8: =AG8*AL8 -> 101089.5
B9: 개발 | C9: 디자인 | D9: (주)위엠비 | E9: 위엠비_개발 | F9: 책임(A) | G9: 개_초 | H9: 김령희 | T9: 1 | AG9: =SUM(I9:AF9) -> 1 | AH9: =SUM(I9:T9) -> 1 | AI9: =SUM(U9:AF9) -> 0 | AJ9: 0 | AK9: =AG9*AJ9 -> 0 | AL9: =IF($E9="위엠비_컨설팅",SUMPRODUCT(($F9='기준-단가'!$C$5:$C$11)*('기준-단가'!$H$5:$H$11)), IF($E9="위엠비_개발",SUMPRODUCT(($F9='기준-단가'!$C$13:$C$19)*('기준-단가'!$H$13:$H$19)), IF($E9="외주_컨설팅",SUMPRODUCT(($G9='기준-단가'!$D$21:$D$24)*('기준-단가'!$H$21:$H$24)), IF($E9="외주_개발",SUMPRODUCT(($G9='기준-단가'!$D$26:$D$29)*('기준-단가'!$H$26:$H$29)))))) -> 10016 | AM9: =AG9*AL9 -> 10016
B10: 개발 | C10: 디자인 | D10: (주)위엠비 | E10: 위엠비_개발 | F10: 수석(L) | G10: 개_고 | H10: 추민욱 | V10: 1 | AG10: =SUM(I10:AF10) -> 1 | AH10: =SUM(I10:T10) -> 0 | AI10: =SUM(U10:AF10) -> 1 | AJ10: 0 | AK10: =AG10*AJ10 -> 0 | AL10: =IF($E10="위엠비_컨설팅",SUMPRODUCT(($F10='기준-단가'!$C$5:$C$11)*('기준-단가'!$H$5:$H$11)), IF($E10="위엠비_개발",SUMPRODUCT(($F10='기준-단가'!$C$13:$C$19)*('기준-단가'!$H$13:$H$19)), IF($E10="외주_컨설팅",SUMPRODUCT(($G10='기준-단가'!$D$21:$D$24)*('기준-단가'!$H$21:$H$24)), IF($E10="외주_개발",SUMPRODUCT(($G10='기준-단가'!$D$26:$D$29)*('기준-단가'!$H$26:$H$29)))))) -> 12391 | AM10: =AG10*AL10 -> 12391
B11: 개발 | C11: 화면 개발 | D11: (주)위엠비 | E11: 위엠비_개발 | F11: 수석(S) | G11: 개_고 | H11: 김대우 | T11: 0.5 | U11: 1 | AG11: =SUM(I11:AF11) -> 1.5 | AH11: =SUM(I11:T11) -> 0.5 | AI11: =SUM(U11:AF11) -> 1 | AJ11: 0 | AK11: =AG11*AJ11 -> 0 | AL11: =IF($E11="위엠비_컨설팅",SUMPRODUCT(($F11='기준-단가'!$C$5:$C$11)*('기준-단가'!$H$5:$H$11)), IF($E11="위엠비_개발",SUMPRODUCT(($F11='기준-단가'!$C$13:$C$19)*('기준-단가'!$H$13:$H$19)), IF($E11="외주_컨설팅",SUMPRODUCT(($G11='기준-단가'!$D$21:$D$24)*('기준-단가'!$H$21:$H$24)), IF($E11="외주_개발",SUMPRODUCT(($G11='기준-단가'!$D$26:$D$29)*('기준-단가'!$H$26:$H$29)))))) -> 11516 | AM11: =AG11*AL11 -> 17274
B12: 개발 | C12: 드로잉, 검수 | D12: (주)위엠비 | E12: 외주_개발 | F12: X | G12: 개_초 | H12: 아르바이트 | U12: 2 | V12: 2 | W12: 2 | X12: 2 | Y12: 3 | Z12: 3 | AA12: 3 | AB12: 3 | AC12: 3 | AG12: =SUM(I12:AF12) -> 23 | AH12: =SUM(I12:T12) -> 0 | AI12: =SUM(U12:AF12) -> 23 | AJ12: 0 | AK12: =AG12*AJ12 -> 0 | AL12: 2150 | AM12: =AG12*AL12 -> 49450
B13: 컨설팅 | C13: 컨설팅 | E13: 외주_컨설팅 | F13: X | G13: 컨_특 | H13: 김철원 | AJ13: 0 | AK13: 0 | AM13: =AK6*10% -> 68530
B14: 소계 | I14: =SUM(I6:I12) -> 0 | J14: =SUM(J6:J12) -> 0 | K14: =SUM(K6:K12) -> 0 | L14: =SUM(L6:L12) -> 0 | M14: =SUM(M6:M12) -> 0 | N14: =SUM(N6:N12) -> 0 | O14: =SUM(O6:O12) -> 0 | P14: =SUM(P6:P12) -> 0 | ... R14: =SUM(R6:R12) -> 0 | S14: =SUM(S6:S13) -> 0.25 | T14: =SUM(T6:T13) -> 4.5 | U14: =SUM(U6:U13) -> 6 | V14: =SUM(V6:V13) -> 6 | W14: =SUM(W6:W13) -> 5 | X14: =SUM(X6:X13) -> 5 | Y14: =SUM(Y6:Y13) -> 6 | Z14: =SUM(Z6:Z13) -> 6 | ... AB14: =SUM(AB6:AB13) -> 6 | AC14: =SUM(AC6:AC12) -> 4.5 | AD14: =SUM(AD6:AD12) -> 0 | AE14: =SUM(AE6:AE12) -> 0 | AF14: =SUM(AF6:AF12) -> 0 | AG14: =SUM(AG6:AG13) -> 55.25 | AH14: =SUM(AH6:AH13) -> 4.75 | AI14: =SUM(AI6:AI13) -> 50.5 | AJ14: =AK14/AG14 -> 12403.62 | AK14: =SUM(AK6:AK12) -> 685300 | AL14: =AM14/AG14 -> 9242.6878 | AM14: =SUM(AM6:AM13) -> 510658.5
A15: 합계(소계 자동 계산) | I15: =SUMPRODUCT(($B$14:$B$14="소계")*(I$14:I$14)) -> 0 | J15: =SUMPRODUCT(($B$14:$B$14="소계")*(J$14:J$14)) -> 0 | K15: =SUMPRODUCT(($B$14:$B$14="소계")*(K$14:K$14)) -> 0 | L15: =SUMPRODUCT(($B$14:$B$14="소계")*(L$14:L$14)) -> 0 | M15: =SUMPRODUCT(($B$14:$B$14="소계")*(M$14:M$14)) -> 0 | N15: =SUMPRODUCT(($B$14:$B$14="소계")*(N$14:N$14)) -> 0 | O15: =SUMPRODUCT(($B$14:$B$14="소계")*(O$14:O$14)) -> 0 | P15: =SUMPRODUCT(($B$14:$B$14="소계")*(P$14:P$14)) -> 0 | ... AI15: =SUMPRODUCT(($B$14:$B$14="소계")*(AI$14:AI$14)) -> 50.5 | AJ15: =AK15/AG15 -> 12403.62 | AK15: =SUMPRODUCT(($B$14:$B$14="소계")*(AK$14:AK$14)) -> 685300 | AL15: =AM15/AG15 -> 9242.6878 | AM15: =SUMPRODUCT(($B$14:$B$14="소계")*(AM$14:AM$14)) -> 510658.5
AK16: =AK15*1.1 -> 753830
A17: [ 분석 : 업체별-등급별 매출 및 원가 ]
D18: 당사 | E18: 위엠비_컨설팅 | G18: 상무 | I18: =SUMPRODUCT(($E$6:$E$12=$E18)*($G18=$F$6:$F$12)*(I$6:I$12)) -> 0 | J18: =SUMPRODUCT(($E$6:$E$12=$E18)*($G18=$F$6:$F$12)*(J$6:J$12)) -> 0 | K18: =SUMPRODUCT(($E$6:$E$12=$E18)*($G18=$F$6:$F$12)*(K$6:K$12)) -> 0 | L18: =SUMPRODUCT(($E$6:$E$12=$E18)*($G18=$F$6:$F$12)*(L$6:L$12)) -> 0 | M18: =SUMPRODUCT(($E$6:$E$12=$E18)*($G18=$F$6:$F$12)*(M$6:M$12)) -> 0 | N18: =SUMPRODUCT(($E$6:$E$12=$E18)*($G18=$F$6:$F$12)*(N$6:N$12)) -> 0 | O18: =SUMPRODUCT(($E$6:$E$12=$E18)*($G18=$F$6:$F$12)*(O$6:O$12)) -> 0 | P18: =SUMPRODUCT(($E$6:$E$12=$E18)*($G18=$F$6:$F$12)*(P$6:P$12)) -> 0 | ... AM18: =SUMPRODUCT(($E$6:$E$12=$E18)*($G18=$F$6:$F$12)*(AM$6:AM$12)) -> 0
E19: 위엠비_컨설팅 | G19: 이사 | I19: =SUMPRODUCT(($E$6:$E$12=$E19)*($G19=$F$6:$F$12)*(I$6:I$12)) -> 0 | J19: =SUMPRODUCT(($E$6:$E$12=$E19)*($G19=$F$6:$F$12)*(J$6:J$12)) -> 0 | K19: =SUMPRODUCT(($E$6:$E$12=$E19)*($G19=$F$6:$F$12)*(K$6:K$12)) -> 0 | L19: =SUMPRODUCT(($E$6:$E$12=$E19)*($G19=$F$6:$F$12)*(L$6:L$12)) -> 0 | M19: =SUMPRODUCT(($E$6:$E$12=$E19)*($G19=$F$6:$F$12)*(M$6:M$12)) -> 0 | N19: =SUMPRODUCT(($E$6:$E$12=$E19)*($G19=$F$6:$F$12)*(N$6:N$12)) -> 0 | O19: =SUMPRODUCT(($E$6:$E$12=$E19)*($G19=$F$6:$F$12)*(O$6:O$12)) -> 0 | P19: =SUMPRODUCT(($E$6:$E$12=$E19)*($G19=$F$6:$F$12)*(P$6:P$12)) -> 0 | ... AM19: =SUMPRODUCT(($E$6:$E$12=$E19)*($G19=$F$6:$F$12)*(AM$6:AM$12)) -> 0
E20: 위엠비_컨설팅 | G20: 수석(L) | I20: =SUMPRODUCT(($E$6:$E$12=$E20)*($G20=$F$6:$F$12)*(I$6:I$12)) -> 0 | J20: =SUMPRODUCT(($E$6:$E$12=$E20)*($G20=$F$6:$F$12)*(J$6:J$12)) -> 0 | K20: =SUMPRODUCT(($E$6:$E$12=$E20)*($G20=$F$6:$F$12)*(K$6:K$12)) -> 0 | L20: =SUMPRODUCT(($E$6:$E$12=$E20)*($G20=$F$6:$F$12)*(L$6:L$12)) -> 0 | M20: =SUMPRODUCT(($E$6:$E$12=$E20)*($G20=$F$6:$F$12)*(M$6:M$12)) -> 0 | N20: =SUMPRODUCT(($E$6:$E$12=$E20)*($G20=$F$6:$F$12)*(N$6:N$12)) -> 0 | O20: =SUMPRODUCT(($E$6:$E$12=$E20)*($G20=$F$6:$F$12)*(O$6:O$12)) -> 0 | P20: =SUMPRODUCT(($E$6:$E$12=$E20)*($G20=$F$6:$F$12)*(P$6:P$12)) -> 0 | ... AM20: =SUMPRODUCT(($E$6:$E$12=$E20)*($G20=$F$6:$F$12)*(AM$6:AM$12)) -> 0
E21: 위엠비_컨설팅 | G21: 수석(S) | I21: =SUMPRODUCT(($E$6:$E$12=$E21)*($G21=$F$6:$F$12)*(I$6:I$12)) -> 0 | J21: =SUMPRODUCT(($E$6:$E$12=$E21)*($G21=$F$6:$F$12)*(J$6:J$12)) -> 0 | K21: =SUMPRODUCT(($E$6:$E$12=$E21)*($G21=$F$6:$F$12)*(K$6:K$12)) -> 0 | L21: =SUMPRODUCT(($E$6:$E$12=$E21)*($G21=$F$6:$F$12)*(L$6:L$12)) -> 0 | M21: =SUMPRODUCT(($E$6:$E$12=$E21)*($G21=$F$6:$F$12)*(M$6:M$12)) -> 0 | N21: =SUMPRODUCT(($E$6:$E$12=$E21)*($G21=$F$6:$F$12)*(N$6:N$12)) -> 0 | O21: =SUMPRODUCT(($E$6:$E$12=$E21)*($G21=$F$6:$F$12)*(O$6:O$12)) -> 0 | P21: =SUMPRODUCT(($E$6:$E$12=$E21)*($G21=$F$6:$F$12)*(P$6:P$12)) -> 0 | ... AM21: =SUMPRODUCT(($E$6:$E$12=$E21)*($G21=$F$6:$F$12)*(AM$6:AM$12)) -> 0
E22: 위엠비_컨설팅 | G22: 책임(M) | I22: =SUMPRODUCT(($E$6:$E$12=$E22)*($G22=$F$6:$F$12)*(I$6:I$12)) -> 0 | J22: =SUMPRODUCT(($E$6:$E$12=$E22)*($G22=$F$6:$F$12)*(J$6:J$12)) -> 0 | K22: =SUMPRODUCT(($E$6:$E$12=$E22)*($G22=$F$6:$F$12)*(K$6:K$12)) -> 0 | L22: =SUMPRODUCT(($E$6:$E$12=$E22)*($G22=$F$6:$F$12)*(L$6:L$12)) -> 0 | M22: =SUMPRODUCT(($E$6:$E$12=$E22)*($G22=$F$6:$F$12)*(M$6:M$12)) -> 0 | N22: =SUMPRODUCT(($E$6:$E$12=$E22)*($G22=$F$6:$F$12)*(N$6:N$12)) -> 0 | O22: =SUMPRODUCT(($E$6:$E$12=$E22)*($G22=$F$6:$F$12)*(O$6:O$12)) -> 0 | P22: =SUMPRODUCT(($E$6:$E$12=$E22)*($G22=$F$6:$F$12)*(P$6:P$12)) -> 0 | ... AM22: =SUMPRODUCT(($E$6:$E$12=$E22)*($G22=$F$6:$F$12)*(AM$6:AM$12)) -> 0
E23: 위엠비_컨설팅 | G23: 책임(A) | I23: =SUMPRODUCT(($E$6:$E$12=$E23)*($G23=$F$6:$F$12)*(I$6:I$12)) -> 0 | J23: =SUMPRODUCT(($E$6:$E$12=$E23)*($G23=$F$6:$F$12)*(J$6:J$12)) -> 0 | K23: =SUMPRODUCT(($E$6:$E$12=$E23)*($G23=$F$6:$F$12)*(K$6:K$12)) -> 0 | L23: =SUMPRODUCT(($E$6:$E$12=$E23)*($G23=$F$6:$F$12)*(L$6:L$12)) -> 0 | M23: =SUMPRODUCT(($E$6:$E$12=$E23)*($G23=$F$6:$F$12)*(M$6:M$12)) -> 0 | N23: =SUMPRODUCT(($E$6:$E$12=$E23)*($G23=$F$6:$F$12)*(N$6:N$12)) -> 0 | O23: =SUMPRODUCT(($E$6:$E$12=$E23)*($G23=$F$6:$F$12)*(O$6:O$12)) -> 0 | P23: =SUMPRODUCT(($E$6:$E$12=$E23)*($G23=$F$6:$F$12)*(P$6:P$12)) -> 0 | ... AM23: =SUMPRODUCT(($E$6:$E$12=$E23)*($G23=$F$6:$F$12)*(AM$6:AM$12)) -> 0
E24: 위엠비_컨설팅 | G24: 사원 | I24: =SUMPRODUCT(($E$6:$E$12=$E24)*($G24=$F$6:$F$12)*(I$6:I$12)) -> 0 | J24: =SUMPRODUCT(($E$6:$E$12=$E24)*($G24=$F$6:$F$12)*(J$6:J$12)) -> 0 | K24: =SUMPRODUCT(($E$6:$E$12=$E24)*($G24=$F$6:$F$12)*(K$6:K$12)) -> 0 | L24: =SUMPRODUCT(($E$6:$E$12=$E24)*($G24=$F$6:$F$12)*(L$6:L$12)) -> 0 | M24: =SUMPRODUCT(($E$6:$E$12=$E24)*($G24=$F$6:$F$12)*(M$6:M$12)) -> 0 | N24: =SUMPRODUCT(($E$6:$E$12=$E24)*($G24=$F$6:$F$12)*(N$6:N$12)) -> 0 | O24: =SUMPRODUCT(($E$6:$E$12=$E24)*($G24=$F$6:$F$12)*(O$6:O$12)) -> 0 | P24: =SUMPRODUCT(($E$6:$E$12=$E24)*($G24=$F$6:$F$12)*(P$6:P$12)) -> 0 | ... AM24: =SUMPRODUCT(($E$6:$E$12=$E24)*($G24=$F$6:$F$12)*(AM$6:AM$12)) -> 0
E25: 소계 | I25: =SUMPRODUCT(($E$6:$E$12=$E25)*($G25=$F$6:$F$12)*(I$6:I$12)) -> 0 | J25: =SUMPRODUCT(($E$6:$E$12=$E25)*($G25=$F$6:$F$12)*(J$6:J$12)) -> 0 | K25: =SUMPRODUCT(($E$6:$E$12=$E25)*($G25=$F$6:$F$12)*(K$6:K$12)) -> 0 | L25: =SUMPRODUCT(($E$6:$E$12=$E25)*($G25=$F$6:$F$12)*(L$6:L$12)) -> 0 | M25: =SUMPRODUCT(($E$6:$E$12=$E25)*($G25=$F$6:$F$12)*(M$6:M$12)) -> 0 | N25: =SUMPRODUCT(($E$6:$E$12=$E25)*($G25=$F$6:$F$12)*(N$6:N$12)) -> 0 | O25: =SUMPRODUCT(($E$6:$E$12=$E25)*($G25=$F$6:$F$12)*(O$6:O$12)) -> 0 | P25: =SUMPRODUCT(($E$6:$E$12=$E25)*($G25=$F$6:$F$12)*(P$6:P$12)) -> 0 | ... AF25: =SUMPRODUCT(($E$6:$E$12=$E25)*($G25=$F$6:$F$12)*(AF$6:AF$12)) -> 0 | AG25: =SUM(AG18:AG24) -> 0 | AH25: =SUM(AH18:AH24) -> 0 | AI25: =SUM(AI18:AI24) -> 0 | AJ25: =IF(AK25>0, AK25/AG25, 0) -> 0 | AK25: =SUM(AK18:AK24) -> 0 | AL25: =IF(AM25>0, AM25/AG25, 0) -> 0 | AM25: =SUM(AM18:AM24) -> 0
E26: 위엠비_개발 | G26: 상무 | I26: =SUMPRODUCT(($E$6:$E$12=$E26)*($G26=$F$6:$F$12)*(I$6:I$12)) -> 0 | J26: =SUMPRODUCT(($E$6:$E$12=$E26)*($G26=$F$6:$F$12)*(J$6:J$12)) -> 0 | K26: =SUMPRODUCT(($E$6:$E$12=$E26)*($G26=$F$6:$F$12)*(K$6:K$12)) -> 0 | L26: =SUMPRODUCT(($E$6:$E$12=$E26)*($G26=$F$6:$F$12)*(L$6:L$12)) -> 0 | M26: =SUMPRODUCT(($E$6:$E$12=$E26)*($G26=$F$6:$F$12)*(M$6:M$12)) -> 0 | N26: =SUMPRODUCT(($E$6:$E$12=$E26)*($G26=$F$6:$F$12)*(N$6:N$12)) -> 0 | O26: =SUMPRODUCT(($E$6:$E$12=$E26)*($G26=$F$6:$F$12)*(O$6:O$12)) -> 0 | P26: =SUMPRODUCT(($E$6:$E$12=$E26)*($G26=$F$6:$F$12)*(P$6:P$12)) -> 0 | ... AM26: =SUMPRODUCT(($E$6:$E$12=$E26)*($G26=$F$6:$F$12)*(AM$6:AM$12)) -> 0
E27: 위엠비_개발 | G27: 이사 | I27: =SUMPRODUCT(($E$6:$E$12=$E27)*($G27=$F$6:$F$12)*(I$6:I$12)) -> 0 | J27: =SUMPRODUCT(($E$6:$E$12=$E27)*($G27=$F$6:$F$12)*(J$6:J$12)) -> 0 | K27: =SUMPRODUCT(($E$6:$E$12=$E27)*($G27=$F$6:$F$12)*(K$6:K$12)) -> 0 | L27: =SUMPRODUCT(($E$6:$E$12=$E27)*($G27=$F$6:$F$12)*(L$6:L$12)) -> 0 | M27: =SUMPRODUCT(($E$6:$E$12=$E27)*($G27=$F$6:$F$12)*(M$6:M$12)) -> 0 | N27: =SUMPRODUCT(($E$6:$E$12=$E27)*($G27=$F$6:$F$12)*(N$6:N$12)) -> 0 | O27: =SUMPRODUCT(($E$6:$E$12=$E27)*($G27=$F$6:$F$12)*(O$6:O$12)) -> 0 | P27: =SUMPRODUCT(($E$6:$E$12=$E27)*($G27=$F$6:$F$12)*(P$6:P$12)) -> 0 | ... AM27: =SUMPRODUCT(($E$6:$E$12=$E27)*($G27=$F$6:$F$12)*(AM$6:AM$12)) -> 142506
E28: 위엠비_개발 | G28: 수석(L) | I28: =SUMPRODUCT(($E$6:$E$12=$E28)*($G28=$F$6:$F$12)*(I$6:I$12)) -> 0 | J28: =SUMPRODUCT(($E$6:$E$12=$E28)*($G28=$F$6:$F$12)*(J$6:J$12)) -> 0 | K28: =SUMPRODUCT(($E$6:$E$12=$E28)*($G28=$F$6:$F$12)*(K$6:K$12)) -> 0 | L28: =SUMPRODUCT(($E$6:$E$12=$E28)*($G28=$F$6:$F$12)*(L$6:L$12)) -> 0 | M28: =SUMPRODUCT(($E$6:$E$12=$E28)*($G28=$F$6:$F$12)*(M$6:M$12)) -> 0 | N28: =SUMPRODUCT(($E$6:$E$12=$E28)*($G28=$F$6:$F$12)*(N$6:N$12)) -> 0 | O28: =SUMPRODUCT(($E$6:$E$12=$E28)*($G28=$F$6:$F$12)*(O$6:O$12)) -> 0 | P28: =SUMPRODUCT(($E$6:$E$12=$E28)*($G28=$F$6:$F$12)*(P$6:P$12)) -> 0 | ... AM28: =SUMPRODUCT(($E$6:$E$12=$E28)*($G28=$F$6:$F$12)*(AM$6:AM$12)) -> 12391
E29: 위엠비_개발 | G29: 수석(S) | I29: =SUMPRODUCT(($E$6:$E$12=$E29)*($G29=$F$6:$F$12)*(I$6:I$12)) -> 0 | J29: =SUMPRODUCT(($E$6:$E$12=$E29)*($G29=$F$6:$F$12)*(J$6:J$12)) -> 0 | K29: =SUMPRODUCT(($E$6:$E$12=$E29)*($G29=$F$6:$F$12)*(K$6:K$12)) -> 0 | L29: =SUMPRODUCT(($E$6:$E$12=$E29)*($G29=$F$6:$F$12)*(L$6:L$12)) -> 0 | M29: =SUMPRODUCT(($E$6:$E$12=$E29)*($G29=$F$6:$F$12)*(M$6:M$12)) -> 0 | N29: =SUMPRODUCT(($E$6:$E$12=$E29)*($G29=$F$6:$F$12)*(N$6:N$12)) -> 0 | O29: =SUMPRODUCT(($E$6:$E$12=$E29)*($G29=$F$6:$F$12)*(O$6:O$12)) -> 0 | P29: =SUMPRODUCT(($E$6:$E$12=$E29)*($G29=$F$6:$F$12)*(P$6:P$12)) -> 0 | ... AM29: =SUMPRODUCT(($E$6:$E$12=$E29)*($G29=$F$6:$F$12)*(AM$6:AM$12)) -> 126676
E30: 위엠비_개발 | G30: 책임(M) | I30: =SUMPRODUCT(($E$6:$E$12=$E30)*($G30=$F$6:$F$12)*(I$6:I$12)) -> 0 | J30: =SUMPRODUCT(($E$6:$E$12=$E30)*($G30=$F$6:$F$12)*(J$6:J$12)) -> 0 | K30: =SUMPRODUCT(($E$6:$E$12=$E30)*($G30=$F$6:$F$12)*(K$6:K$12)) -> 0 | L30: =SUMPRODUCT(($E$6:$E$12=$E30)*($G30=$F$6:$F$12)*(L$6:L$12)) -> 0 | M30: =SUMPRODUCT(($E$6:$E$12=$E30)*($G30=$F$6:$F$12)*(M$6:M$12)) -> 0 | N30: =SUMPRODUCT(($E$6:$E$12=$E30)*($G30=$F$6:$F$12)*(N$6:N$12)) -> 0 | O30: =SUMPRODUCT(($E$6:$E$12=$E30)*($G30=$F$6:$F$12)*(O$6:O$12)) -> 0 | P30: =SUMPRODUCT(($E$6:$E$12=$E30)*($G30=$F$6:$F$12)*(P$6:P$12)) -> 0 | ... AM30: =SUMPRODUCT(($E$6:$E$12=$E30)*($G30=$F$6:$F$12)*(AM$6:AM$12)) -> 101089.5
E31: 위엠비_개발 | G31: 책임(A) | I31: =SUMPRODUCT(($E$6:$E$12=$E31)*($G31=$F$6:$F$12)*(I$6:I$12)) -> 0 | J31: =SUMPRODUCT(($E$6:$E$12=$E31)*($G31=$F$6:$F$12)*(J$6:J$12)) -> 0 | K31: =SUMPRODUCT(($E$6:$E$12=$E31)*($G31=$F$6:$F$12)*(K$6:K$12)) -> 0 | L31: =SUMPRODUCT(($E$6:$E$12=$E31)*($G31=$F$6:$F$12)*(L$6:L$12)) -> 0 | M31: =SUMPRODUCT(($E$6:$E$12=$E31)*($G31=$F$6:$F$12)*(M$6:M$12)) -> 0 | N31: =SUMPRODUCT(($E$6:$E$12=$E31)*($G31=$F$6:$F$12)*(N$6:N$12)) -> 0 | O31: =SUMPRODUCT(($E$6:$E$12=$E31)*($G31=$F$6:$F$12)*(O$6:O$12)) -> 0 | P31: =SUMPRODUCT(($E$6:$E$12=$E31)*($G31=$F$6:$F$12)*(P$6:P$12)) -> 0 | ... AM31: =SUMPRODUCT(($E$6:$E$12=$E31)*($G31=$F$6:$F$12)*(AM$6:AM$12)) -> 10016
E32: 위엠비_개발 | G32: 사원 | I32: =SUMPRODUCT(($E$6:$E$12=$E32)*($G32=$F$6:$F$12)*(I$6:I$12)) -> 0 | J32: =SUMPRODUCT(($E$6:$E$12=$E32)*($G32=$F$6:$F$12)*(J$6:J$12)) -> 0 | K32: =SUMPRODUCT(($E$6:$E$12=$E32)*($G32=$F$6:$F$12)*(K$6:K$12)) -> 0 | L32: =SUMPRODUCT(($E$6:$E$12=$E32)*($G32=$F$6:$F$12)*(L$6:L$12)) -> 0 | M32: =SUMPRODUCT(($E$6:$E$12=$E32)*($G32=$F$6:$F$12)*(M$6:M$12)) -> 0 | N32: =SUMPRODUCT(($E$6:$E$12=$E32)*($G32=$F$6:$F$12)*(N$6:N$12)) -> 0 | O32: =SUMPRODUCT(($E$6:$E$12=$E32)*($G32=$F$6:$F$12)*(O$6:O$12)) -> 0 | P32: =SUMPRODUCT(($E$6:$E$12=$E32)*($G32=$F$6:$F$12)*(P$6:P$12)) -> 0 | ... AM32: =SUMPRODUCT(($E$6:$E$12=$E32)*($G32=$F$6:$F$12)*(AM$6:AM$12)) -> 0
E33: 소계 | I33: =SUM(I26:I32) -> 0 | J33: =SUM(J26:J32) -> 0 | K33: =SUM(K26:K32) -> 0 | L33: =SUM(L26:L32) -> 0 | M33: =SUM(M26:M32) -> 0 | N33: =SUM(N26:N32) -> 0 | O33: =SUM(O26:O32) -> 0 | P33: =SUM(P26:P32) -> 0 | ... AI33: =SUM(AI26:AI32) -> 27.5 | AJ33: =IF(AK33>0, AK33/AG33, 0) -> 21249.612 | AK33: =SUM(AK26:AK32) -> 685300 | AL33: =IF(AM33>0, AM33/AG33, 0) -> 12176.078 | AM33: =SUM(AM26:AM32) -> 392678.5
E34: 당사 소계 | I34: =SUM(I33,I25) -> 0 | J34: =SUM(J33,J25) -> 0 | K34: =SUM(K33,K25) -> 0 | L34: =SUM(L33,L25) -> 0 | M34: =SUM(M33,M25) -> 0 | N34: =SUM(N33,N25) -> 0 | O34: =SUM(O33,O25) -> 0 | P34: =SUM(P33,P25) -> 0 | ... AM34: =SUM(AM33,AM25) -> 392678.5
D35: 외주 | E35: 외주_컨설팅 | G35: 컨_특 | I35: =SUMPRODUCT(($E$6:$E$12=$E35)*($G35=$G$6:$G$12)*(I$6:I$12)) -> 0 | J35: =SUMPRODUCT(($E$6:$E$12=$E35)*($G35=$G$6:$G$12)*(J$6:J$12)) -> 0 | K35: =SUMPRODUCT(($E$6:$E$12=$E35)*($G35=$G$6:$G$12)*(K$6:K$12)) -> 0 | L35: =SUMPRODUCT(($E$6:$E$12=$E35)*($G35=$G$6:$G$12)*(L$6:L$12)) -> 0 | M35: =SUMPRODUCT(($E$6:$E$12=$E35)*($G35=$G$6:$G$12)*(M$6:M$12)) -> 0 | N35: =SUMPRODUCT(($E$6:$E$12=$E35)*($G35=$G$6:$G$12)*(N$6:N$12)) -> 0 | O35: =SUMPRODUCT(($E$6:$E$12=$E35)*($G35=$G$6:$G$12)*(O$6:O$12)) -> 0 | P35: =SUMPRODUCT(($E$6:$E$12=$E35)*($G35=$G$6:$G$12)*(P$6:P$12)) -> 0 | ... AF35: =SUMPRODUCT(($E$6:$E$12=$E35)*($G35=$G$6:$G$12)*(AF$6:AF$12)) -> 0 | AG35: =SUMPRODUCT(($E$6:$E$13=$E35)*($G35=$G$6:$G$13)*(AG$6:AG$13)) -> 0 | AH35: =SUMPRODUCT(($E$6:$E$12=$E35)*($G35=$G$6:$G$12)*(AH$6:AH$12)) -> 0 | AI35: =SUMPRODUCT(($E$6:$E$12=$E35)*($G35=$G$6:$G$12)*(AI$6:AI$12)) -> 0 | AJ35: =SUMPRODUCT(($E$6:$E$12=$E35)*($G35=$G$6:$G$12)*(AJ$6:AJ$12)) -> 0 | AK35: =SUMPRODUCT(($E$6:$E$12=$E35)*($G35=$G$6:$G$12)*(AK$6:AK$12)) -> 0 | AL35: =SUMPRODUCT(($E$6:$E$12=$E35)*($G35=$G$6:$G$12)*(AL$6:AL$12)) -> 0 | AM35: =SUMPRODUCT(($E$6:$E$13=$E35)*($G35=$G$6:$G$13)*(AM$6:AM$13)) -> 68530
E36: 외주_컨설팅 | G36: 컨_고 | I36: =SUMPRODUCT(($E$6:$E$12=$E36)*($G36=$G$6:$G$12)*(I$6:I$12)) -> 0 | J36: =SUMPRODUCT(($E$6:$E$12=$E36)*($G36=$G$6:$G$12)*(J$6:J$12)) -> 0 | K36: =SUMPRODUCT(($E$6:$E$12=$E36)*($G36=$G$6:$G$12)*(K$6:K$12)) -> 0 | L36: =SUMPRODUCT(($E$6:$E$12=$E36)*($G36=$G$6:$G$12)*(L$6:L$12)) -> 0 | M36: =SUMPRODUCT(($E$6:$E$12=$E36)*($G36=$G$6:$G$12)*(M$6:M$12)) -> 0 | N36: =SUMPRODUCT(($E$6:$E$12=$E36)*($G36=$G$6:$G$12)*(N$6:N$12)) -> 0 | O36: =SUMPRODUCT(($E$6:$E$12=$E36)*($G36=$G$6:$G$12)*(O$6:O$12)) -> 0 | P36: =SUMPRODUCT(($E$6:$E$12=$E36)*($G36=$G$6:$G$12)*(P$6:P$12)) -> 0 | ... AF36: =SUMPRODUCT(($E$6:$E$12=$E36)*($G36=$G$6:$G$12)*(AF$6:AF$12)) -> 0 | AG36: =SUMPRODUCT(($E$6:$E$13=$E36)*($G36=$G$6:$G$13)*(AG$6:AG$13)) -> 0 | AH36: =SUMPRODUCT(($E$6:$E$12=$E36)*($G36=$G$6:$G$12)*(AH$6:AH$12)) -> 0 | AI36: =SUMPRODUCT(($E$6:$E$12=$E36)*($G36=$G$6:$G$12)*(AI$6:AI$12)) -> 0 | AJ36: =SUMPRODUCT(($E$6:$E$12=$E36)*($G36=$G$6:$G$12)*(AJ$6:AJ$12)) -> 0 | AK36: =SUMPRODUCT(($E$6:$E$12=$E36)*($G36=$G$6:$G$12)*(AK$6:AK$12)) -> 0 | AL36: =SUMPRODUCT(($E$6:$E$12=$E36)*($G36=$G$6:$G$12)*(AL$6:AL$12)) -> 0 | AM36: =SUMPRODUCT(($E$6:$E$13=$E36)*($G36=$G$6:$G$13)*(AM$6:AM$13)) -> 0
E37: 외주_컨설팅 | G37: 컨_중 | I37: =SUMPRODUCT(($E$6:$E$12=$E37)*($G37=$G$6:$G$12)*(I$6:I$12)) -> 0 | J37: =SUMPRODUCT(($E$6:$E$12=$E37)*($G37=$G$6:$G$12)*(J$6:J$12)) -> 0 | K37: =SUMPRODUCT(($E$6:$E$12=$E37)*($G37=$G$6:$G$12)*(K$6:K$12)) -> 0 | L37: =SUMPRODUCT(($E$6:$E$12=$E37)*($G37=$G$6:$G$12)*(L$6:L$12)) -> 0 | M37: =SUMPRODUCT(($E$6:$E$12=$E37)*($G37=$G$6:$G$12)*(M$6:M$12)) -> 0 | N37: =SUMPRODUCT(($E$6:$E$12=$E37)*($G37=$G$6:$G$12)*(N$6:N$12)) -> 0 | O37: =SUMPRODUCT(($E$6:$E$12=$E37)*($G37=$G$6:$G$12)*(O$6:O$12)) -> 0 | P37: =SUMPRODUCT(($E$6:$E$12=$E37)*($G37=$G$6:$G$12)*(P$6:P$12)) -> 0 | ... AF37: =SUMPRODUCT(($E$6:$E$12=$E37)*($G37=$G$6:$G$12)*(AF$6:AF$12)) -> 0 | AG37: =SUMPRODUCT(($E$6:$E$13=$E37)*($G37=$G$6:$G$13)*(AG$6:AG$13)) -> 0 | AH37: =SUMPRODUCT(($E$6:$E$12=$E37)*($G37=$G$6:$G$12)*(AH$6:AH$12)) -> 0 | AI37: =SUMPRODUCT(($E$6:$E$12=$E37)*($G37=$G$6:$G$12)*(AI$6:AI$12)) -> 0 | AJ37: =SUMPRODUCT(($E$6:$E$12=$E37)*($G37=$G$6:$G$12)*(AJ$6:AJ$12)) -> 0 | AK37: =SUMPRODUCT(($E$6:$E$12=$E37)*($G37=$G$6:$G$12)*(AK$6:AK$12)) -> 0 | AL37: =SUMPRODUCT(($E$6:$E$12=$E37)*($G37=$G$6:$G$12)*(AL$6:AL$12)) -> 0 | AM37: =SUMPRODUCT(($E$6:$E$13=$E37)*($G37=$G$6:$G$13)*(AM$6:AM$13)) -> 0
E38: 외주_컨설팅 | G38: 컨_초 | I38: =SUMPRODUCT(($E$6:$E$12=$E38)*($G38=$G$6:$G$12)*(I$6:I$12)) -> 0 | J38: =SUMPRODUCT(($E$6:$E$12=$E38)*($G38=$G$6:$G$12)*(J$6:J$12)) -> 0 | K38: =SUMPRODUCT(($E$6:$E$12=$E38)*($G38=$G$6:$G$12)*(K$6:K$12)) -> 0 | L38: =SUMPRODUCT(($E$6:$E$12=$E38)*($G38=$G$6:$G$12)*(L$6:L$12)) -> 0 | M38: =SUMPRODUCT(($E$6:$E$12=$E38)*($G38=$G$6:$G$12)*(M$6:M$12)) -> 0 | N38: =SUMPRODUCT(($E$6:$E$12=$E38)*($G38=$G$6:$G$12)*(N$6:N$12)) -> 0 | O38: =SUMPRODUCT(($E$6:$E$12=$E38)*($G38=$G$6:$G$12)*(O$6:O$12)) -> 0 | P38: =SUMPRODUCT(($E$6:$E$12=$E38)*($G38=$G$6:$G$12)*(P$6:P$12)) -> 0 | ... AF38: =SUMPRODUCT(($E$6:$E$12=$E38)*($G38=$G$6:$G$12)*(AF$6:AF$12)) -> 0 | AG38: =SUMPRODUCT(($E$6:$E$13=$E38)*($G38=$G$6:$G$13)*(AG$6:AG$13)) -> 0 | AH38: =SUMPRODUCT(($E$6:$E$12=$E38)*($G38=$G$6:$G$12)*(AH$6:AH$12)) -> 0 | AI38: =SUMPRODUCT(($E$6:$E$12=$E38)*($G38=$G$6:$G$12)*(AI$6:AI$12)) -> 0 | AJ38: =SUMPRODUCT(($E$6:$E$12=$E38)*($G38=$G$6:$G$12)*(AJ$6:AJ$12)) -> 0 | AK38: =SUMPRODUCT(($E$6:$E$12=$E38)*($G38=$G$6:$G$12)*(AK$6:AK$12)) -> 0 | AL38: =SUMPRODUCT(($E$6:$E$12=$E38)*($G38=$G$6:$G$12)*(AL$6:AL$12)) -> 0 | AM38: =SUMPRODUCT(($E$6:$E$13=$E38)*($G38=$G$6:$G$13)*(AM$6:AM$13)) -> 0
E39: 소계 | I39: =SUM(I35:I38) -> 0 | J39: =SUM(J35:J38) -> 0 | K39: =SUM(K35:K38) -> 0 | L39: =SUM(L35:L38) -> 0 | M39: =SUM(M35:M38) -> 0 | N39: =SUM(N35:N38) -> 0 | O39: =SUM(O35:O38) -> 0 | P39: =SUM(P35:P38) -> 0 | ... AI39: =SUM(AI35:AI38) -> 0 | AJ39: =IF(AK39>0, AK39/AG39, 0) -> 0 | AK39: =SUM(AK35:AK38) -> 0 | AL39: - | AM39: =SUM(AM35:AM38) -> 68530
E40: 외주_개발 | G40: 개_특 | I40: =SUMPRODUCT(($E$6:$E$12=$E40)*($G40=$G$6:$G$12)*(I$6:I$12)) -> 0 | J40: =SUMPRODUCT(($E$6:$E$12=$E40)*($G40=$G$6:$G$12)*(J$6:J$12)) -> 0 | K40: =SUMPRODUCT(($E$6:$E$12=$E40)*($G40=$G$6:$G$12)*(K$6:K$12)) -> 0 | L40: =SUMPRODUCT(($E$6:$E$12=$E40)*($G40=$G$6:$G$12)*(L$6:L$12)) -> 0 | M40: =SUMPRODUCT(($E$6:$E$12=$E40)*($G40=$G$6:$G$12)*(M$6:M$12)) -> 0 | N40: =SUMPRODUCT(($E$6:$E$12=$E40)*($G40=$G$6:$G$12)*(N$6:N$12)) -> 0 | O40: =SUMPRODUCT(($E$6:$E$12=$E40)*($G40=$G$6:$G$12)*(O$6:O$12)) -> 0 | P40: =SUMPRODUCT(($E$6:$E$12=$E40)*($G40=$G$6:$G$12)*(P$6:P$12)) -> 0 | ... AM40: =SUMPRODUCT(($E$6:$E$12=$E40)*($G40=$G$6:$G$12)*(AM$6:AM$12)) -> 0
...

Sheet 프로젝트경비
A1: [ 프 로 젝 트 경 비 ] | F1: **색 표시란만 조정하세요!
R2: (단위:천원)
A3: 구분 | C3: 총투입 MM | F3: 당년 | R3: 차년
C4: 합계 | D4: 당년 | E4: 차년 | F4: 1월 | G4: 2월 | H4: 3월 | I4: 4월 | J4: 5월 | K4: 6월 | L4: 7월 | M4: 8월 | N4: 9월 | O4: 10월 | P4: 11월 | Q4: 12월 | R4: 01월 | S4: 2월 | T4: 3월 | U4: 4월 | V4: 5월 | W4: 6월 | X4: 7월 | Y4: 8월 | Z4: 9월 | AA4: 10월 | AB4: 11월 | AC4: 12월
A5: 투여공수 | B5: 내부 | C5: =SUM(D5:E5) -> 32.25 | D5: =SUM(F5:Q5) -> 4.75 | E5: =SUM(R5:AC5) -> 27.5 | F5: =인력계획!I34 -> 0 | G5: =인력계획!J34 -> 0 | H5: =인력계획!K34 -> 0 | I5: =인력계획!L34 -> 0 | J5: =인력계획!M34 -> 0 | K5: =인력계획!N34 -> 0 | L5: =인력계획!O34 -> 0 | M5: =인력계획!P34 -> 0 | ... AC5: =인력계획!AF34 -> 0
B6: 외주 | C6: =SUM(D6:E6) -> 23 | D6: =SUM(F6:Q6) -> 0 | E6: =SUM(R6:AC6) -> 23 | F6: =인력계획!I45 -> 0 | G6: =인력계획!J45 -> 0 | H6: =인력계획!K45 -> 0 | I6: =인력계획!L45 -> 0 | J6: =인력계획!M45 -> 0 | K6: =인력계획!N45 -> 0 | L6: =인력계획!O45 -> 0 | M6: =인력계획!P45 -> 0 | ... AC6: =인력계획!AF45 -> 0
A7: 일반경비 | B7: 야근식대_당사 | C7: =SUM(D7:E7) -> 0 | D7: =SUM(F7:Q7) -> 0 | E7: =SUM(R7:AC7) -> 0 | F7: ='기준-경비'!$G$4*F5 -> 0 | G7: ='기준-경비'!$G$4*G5 -> 0 | H7: ='기준-경비'!$G$4*H5 -> 0 | I7: ='기준-경비'!$G$4*I5 -> 0 | J7: ='기준-경비'!$G$4*J5 -> 0 | K7: ='기준-경비'!$G$4*K5 -> 0 | L7: ='기준-경비'!$G$4*L5 -> 0 | M7: ='기준-경비'!$G$4*M5 -> 0 | ... AC7: ='기준-경비'!$G$4*AC5 -> 0
B8: 프로젝트부서비(내부) | C8: =SUM(D8:E8) -> 806.25 | D8: =SUM(F8:Q8) -> 118.75 | E8: =SUM(R8:AC8) -> 687.5 | F8: ='기준-경비'!$G$5*F5 -> 0 | G8: ='기준-경비'!$G$5*G5 -> 0 | H8: ='기준-경비'!$G$5*H5 -> 0 | I8: ='기준-경비'!$G$5*I5 -> 0 | J8: ='기준-경비'!$G$5*J5 -> 0 | K8: ='기준-경비'!$G$5*K5 -> 0 | L8: ='기준-경비'!$G$5*L5 -> 0 | M8: ='기준-경비'!$G$5*M5 -> 0 | ... AC8: ='기준-경비'!$G$5*AC5 -> 0
B9: 프로젝트부서비(외주) | C9: =SUM(D9:E9) -> 575 | D9: =SUM(F9:Q9) -> 0 | E9: =SUM(R9:AC9) -> 575 | F9: =F6*'기준-경비'!$G$6 -> 0 | G9: =G6*'기준-경비'!$G$6 -> 0 | H9: =H6*'기준-경비'!$G$6 -> 0 | I9: =I6*'기준-경비'!$G$6 -> 0 | J9: =J6*'기준-경비'!$G$6 -> 0 | K9: =K6*'기준-경비'!$G$6 -> 0 | L9: =L6*'기준-경비'!$G$6 -> 0 | M9: =M6*'기준-경비'!$G$6 -> 0 | ... AC9: =AC6*'기준-경비'!$G$6 -> 0
B10: 소계 | C10: =SUM(D10:E10) -> 1381.25 | D10: =SUM(D7:D9) -> 118.75 | E10: =SUM(E7:E9) -> 1262.5 | F10: =SUM(F7:F9) -> 0 | G10: =SUM(G7:G9) -> 0 | H10: =SUM(H7:H9) -> 0 | I10: =SUM(I7:I9) -> 0 | J10: =SUM(J7:J9) -> 0 | K10: =SUM(K7:K9) -> 0 | ... AC10: =SUM(AC7:AC9) -> 0
A11: 특별경비 | B11: 워크샵 | C11: =SUM(D11:E11) -> 0 | D11: =SUM(F11:Q11) -> 0 | E11: =SUM(R11:AC11) -> 0
B12: Kic-Off비용 | C12: =SUM(D12:E12) -> 4000 | D12: =SUM(F12:Q12) -> 0 | E12: =SUM(R12:AC12) -> 4000 | R12: 2000 | Z12: 2000
B13: 임차비(지방) | C13: =SUM(D13:E13) -> 3000 | D13: =SUM(F13:Q13) -> 300 | E13: =SUM(R13:AC13) -> 2700 | F13: =SUM(F5:F6)*'기준-경비'!$G$9 -> 0 | G13: =SUM(G5:G6)*'기준-경비'!$G$9 -> 0 | H13: =SUM(H5:H6)*'기준-경비'!$G$9 -> 0 | I13: =SUM(I5:I6)*'기준-경비'!$G$9 -> 0 | J13: =SUM(J5:J6)*'기준-경비'!$G$9 -> 0 | K13: =SUM(K5:K6)*'기준-경비'!$G$9 -> 0 | L13: =SUM(L5:L6)*'기준-경비'!$G$9 -> 0 | M13: =SUM(M5:M6)*'기준-경비'!$G$9 -> 0 | ... O13: =SUM(O5:O6)*'기준-경비'!$G$9 -> 0 | P13: 0 | Q13: 300 | R13: 300 | S13: 300 | T13: 300 | U13: 300 | V13: 300 | W13: 300 | X13: 300 | Y13: 300 | Z13: 300 | AA13: =SUM(AA5:AA6)*'기준-경비'!$G$9 -> 0 | AB13: =SUM(AB5:AB6)*'기준-경비'!$G$9 -> 0 | AC13: =SUM(AC5:AC6)*'기준-경비'!$G$9 -> 0
B14: 출장비(지방) | C14: =SUM(D14:E14) -> 6000 | D14: =SUM(F14:Q14) -> 600 | E14: =SUM(R14:AC14) -> 5400 | F14: =F5*'기준-경비'!$G$10 -> 0 | G14: =G5*'기준-경비'!$G$10 -> 0 | H14: =H5*'기준-경비'!$G$10 -> 0 | I14: =I5*'기준-경비'!$G$10 -> 0 | J14: =J5*'기준-경비'!$G$10 -> 0 | K14: =K5*'기준-경비'!$G$10 -> 0 | L14: =L5*'기준-경비'!$G$10 -> 0 | M14: =M5*'기준-경비'!$G$10 -> 0 | O14: 0 | P14: 0 | Q14: 600 | R14: 600 | S14: 600 | T14: 600 | U14: 600 | V14: 600 | W14: 600 | X14: 600 | Y14: 600 | Z14: 600 | AA14: =AA5*'기준-경비'!$G$10 -> 0 | AB14: =AB5*'기준-경비'!$G$10 -> 0 | AC14: =AC5*'기준-경비'!$G$10 -> 0
B15: 교통비(지방) | C15: =SUM(D15:E15) -> 14000 | D15: =SUM(F15:Q15) -> 1000 | E15: =SUM(R15:AC15) -> 13000 | F15: =F5*'기준-경비'!$G$11 -> 0 | G15: =G5*'기준-경비'!$G$11 -> 0 | H15: =H5*'기준-경비'!$G$11 -> 0 | I15: =I5*'기준-경비'!$G$11 -> 0 | J15: =J5*'기준-경비'!$G$11 -> 0 | K15: =K5*'기준-경비'!$G$11 -> 0 | L15: =L5*'기준-경비'!$G$11 -> 0 | M15: 0 | P15: 0 | Q15: 1000 | R15: 1500 | S15: 1500 | T15: 1500 | U15: 1500 | V15: 1500 | W15: 1500 | X15: 1500 | Y15: 1500 | Z15: 1000 | AA15: =SUM(AA5:AA6)*'기준-경비'!$G$11 -> 0 | AB15: =SUM(AB5:AB6)*'기준-경비'!$G$11 -> 0 | AC15: =SUM(AC5:AC6)*'기준-경비'!$G$11 -> 0
B16: 기타(해외출장) | C16: =SUM(D16:E16) -> 13000 | D16: =SUM(F16:Q16) -> 6000 | E16: =SUM(R16:AC16) -> 7000 | O16: 5000 | Q16: 1000 | T16: 7000
B17: 소계 | C17: =SUM(D17:E17) -> 40000 | D17: =SUM(D11:D16) -> 7900 | E17: =SUM(E11:E16) -> 32100 | F17: =SUM(F11:F16) -> 0 | G17: =SUM(G11:G16) -> 0 | H17: =SUM(H11:H16) -> 0 | I17: =SUM(I11:I16) -> 0 | J17: =SUM(J11:J16) -> 0 | K17: =SUM(K11:K16) -> 0 | ... W17: =SUM(W11:W16) -> 2400 | AA17: =SUM(AA11:AA16) -> 0 | AB17: =SUM(AB11:AB16) -> 0 | AC17: =SUM(AC11:AC16) -> 0
A18: 합계 | C18: =SUM(D18:E18) -> 41381.25 | D18: =SUM(D10,D17) -> 8018.75 | E18: =SUM(E10,E17) -> 33362.5 | F18: =SUM(F10,F17) -> 0 | G18: =SUM(G10,G17) -> 0 | H18: =SUM(H10,H17) -> 0 | I18: =SUM(I10,I17) -> 0 | J18: =SUM(J10,J17) -> 0 | K18: =SUM(K10,K17) -> 0 | ... AC18: =SUM(AC10,AC17) -> 0
A19: * 인당 계산되는 소모품비 및 음료대는 당사가 "을"로 계약시에는 당사 및 외주 인력을 합하여 승하고 당사가 "병"이하로 계약시에는 당사 인력 만 승하시기 바랍니다.

Sheet 기준-단가
A1: [ 기 준 단 가 ]
A2: 소속 및 직군 | B2: 직군 | C2: 직급 | D2: 등급 | E2: =TODAY() -> 45643 | J2: =TODAY()-365 -> 45278 | O2: =J2-365 -> 44913
E3: 제안단가 | H3: 내부단가 | J3: 제안단가 | M3: 내부단가 | O3: 제안단가 | R3: 내부단가
E4: 기준 | F4: 적용 | G4: 할인률 | H4: 적용 | I4: 인상율 | J4: 기준 | K4: 적용 | L4: 할인률 | M4: 적용 | N4: 인상율 | O4: 기준 | P4: 적용 | Q4: 할인률 | R4: 적용 | S4: 인상율
A5: 위엠비_컨설팅 | B5: 컨설팅 | C5: 상무 | D5: 특급 | E5: 30000 | F5: 0 | G5: =(E5-F5)/E5 -> 1 | H5: 14516 | I5: =(H5-M5)/M5 -> -0.092239385 | J5: 30000 | K5: 11500 | L5: =(J5-K5)/J5 -> 0.61666667 | M5: 15991 | N5: =(M5-R5)/R5 -> 0.37853448 | O5: 30000 | P5: 11500 | Q5: =(O5-P5)/O5 -> 0.61666667 | R5: 11600 | U5: 2018년 소프트웨어 노임단가표 (VAT별도)
A6: 위엠비_컨설팅 | B6: 컨설팅 | C6: 이사 | D6: 특급 | E6: 25000 | F6: 0 | G6: =(E6-F6)/E6 -> 1 | H6: 14616 | I6: =(H6-M6)/M6 -> 0.20993377 | J6: 25000 | K6: 11500 | L6: =(J6-K6)/J6 -> 0.54 | M6: 12080 | N6: =(M6-R6)/R6 -> 0.37272727 | O6: 25000 | P6: 11500 | Q6: =(O6-P6)/O6 -> 0.54 | R6: 8800 | U6: 21 | V6: 기준단가 | W6: 직접인건비 | X6: 제경비10% | Y6: 기술료20% | Z6: 제안금액
A7: 위엠비_컨설팅 | B7: 컨설팅 | C7: 수석(L) | D7: 고급 | E7: 20000 | F7: 0 | G7: =(E7-F7)/E7 -> 1 | H7: 12391 | I7: =(H7-M7)/M7 -> 0.34699424 | J7: 20000 | K7: 9500 | L7: =(J7-K7)/J7 -> 0.525 | M7: 9199 | N7: =(M7-R7)/R7 -> 0.2956338 | O7: 20000 | P7: 9500 | Q7: =(O7-P7)/O7 -> 0.525 | R7: 7100 | U7: 기술사 | V7: 411642 | W7: =V7*U6 -> 8644482 | X7: =V7*U6*1.1 -> 9508930.2 | Y7: =(W7+X7)*0.2 -> 3630682.4 | Z7: =SUM(W7:Y7) -> 21784095
A8: 위엠비_컨설팅 | B8: 컨설팅 | C8: 수석(S) | D8: 고급 | E8: 16000 | F8: 0 | G8: =(E8-F8)/E8 -> 1 | H8: 11516 | I8: =(H8-M8)/M8 -> 0.54101432 | J8: 16000 | K8: 9500 | L8: =(J8-K8)/J8 -> 0.40625 | M8: 7473 | N8: =(M8-R8)/R8 -> 0.33446429 | O8: 16000 | P8: 9500 | Q8: =(O8-P8)/O8 -> 0.40625 | R8: 5600 | U8: 특급 | V8: 373593 | W8: 8134214 | X8: 8947635.4 | Y8: 3416369.9 | Z8: =SUM(W8:Y8) -> 20498219
A9: 위엠비_컨설팅 | B9: 컨설팅 | C9: 책임(M) | D9: 중급 | E9: 14000 | F9: 0 | G9: =(E9-F9)/E9 -> 1 | H9: 10641 | I9: =(H9-M9)/M9 -> 0.76088036 | J9: 14000 | K9: 7500 | L9: =(J9-K9)/J9 -> 0.46428571 | M9: 6043 | N9: =(M9-R9)/R9 -> 0.25895833 | O9: 14000 | P9: 7500 | Q9: =(O9-P9)/O9 -> 0.46428571 | R9: 4800 | U9: 고급 | V9: 276160 | W9: 6351342 | X9: 6986476.2 | Y9: 2667563.6 | Z9: =SUM(W9:Y9) -> 16005382
A10: 위엠비_컨설팅 | B10: 컨설팅 | C10: 책임(A) | D10: 초급 | E10: 12000 | F10: 0 | G10: =(E10-F10)/E10 -> 1 | H10: 10016 | I10: =(H10-M10)/M10 -> 0.98375916 | J10: 12000 | K10: 7500 | L10: =(J10-K10)/J10 -> 0.375 | M10: 5049 | N10: =(M10-R10)/R10 -> 0.26225 | O10: 12000 | P10: 7500 | Q10: =(O10-P10)/O10 -> 0.375 | R10: 4000 | U10: 중급 | V10: 221375 | W10: 4981725 | X10: 5479897.5 | Y10: 2092324.5 | Z10: =SUM(W10:Y10) -> 12553947
A11: 위엠비_컨설팅 | B11: 컨설팅 | C11: 사원 | D11: 초급 | E11: 10000 | F11: 0 | G11: =(E11-F11)/E11 -> 1 | H11: 6791 | I11: =(H11-M11)/M11 -> 0.64113098 | J11: 10000 | K11: 6000 | L11: =(J11-K11)/J11 -> 0.4 | M11: 4138 | N11: =(M11-R11)/R11 -> 0.293125 | O11: 10000 | P11: 6000 | Q11: =(O11-P11)/O11 -> 0.4 | R11: 3200 | U11: 초급 | V11: 190787 | W11: 3979456 | X11: 4377401.6 | Y11: 1671371.5 | Z11: =SUM(W11:Y11) -> 10028229
A12: 위엠비_컨설팅 | C12: 평균 | F12: =SUM(F5:F11)/7 -> 0 | G12: =AVERAGE(G5:G11) -> 1 | H12: =SUM(H5:H11)/7 -> 11498.143 | I12: =(H12-M12)/M12 -> 0.34205392 | K12: =SUM(K5:K11)/7 -> 9000 | L12: =AVERAGE(L5:L11) -> 0.47531463 | M12: =SUM(M5:M11)/7 -> 8567.5714 | N12: =(M12-R12)/R12 -> 0.32977827 | P12: =SUM(P5:P11)/7 -> 9000 | Q12: =AVERAGE(Q5:Q11) -> 0.47531463 | R12: =SUM(R5:R11)/7 -> 6442.8571
A13: 위엠비_개발 | B13: 개발 | C13: 상무 | D13: 특급 | E13: 20498 | F13: 0 | G13: =(E13-F13)/E13 -> 1 | H13: 14516 | I13: =(H13-M13)/M13 -> -0.092239385 | J13: 20498 | K13: 11500 | L13: =(J13-K13)/J13 -> 0.43896966 | M13: 15991 | N13: =(M13-R13)/R13 -> 0.37853448 | O13: 20498 | P13: 11500 | Q13: =(O13-P13)/O13 -> 0.43896966 | R13: 11600
A14: 위엠비_개발 | B14: 개발 | C14: 이사 | D14: 특급 | E14: 20498 | F14: 0 | G14: =(E14-F14)/E14 -> 1 | H14: 14616 | I14: =(H14-M14)/M14 -> 0.20993377 | J14: 20498 | K14: 11500 | L14: =(J14-K14)/J14 -> 0.43896966 | M14: 12080 | N14: =(M14-R14)/R14 -> 0.37272727 | O14: 20498 | P14: 11500 | Q14: =(O14-P14)/O14 -> 0.43896966 | R14: 8800
A15: 위엠비_개발 | B15: 개발 | C15: 수석(L) | D15: 고급 | E15: 16005 | F15: 0 | G15: =(E15-F15)/E15 -> 1 | H15: 12391 | I15: =(H15-M15)/M15 -> 0.34699424 | J15: 16005 | K15: 9500 | L15: =(J15-K15)/J15 -> 0.40643549 | M15: 9199 | N15: =(M15-R15)/R15 -> 0.2956338 | O15: 16005 | P15: 9500 | Q15: =(O15-P15)/O15 -> 0.40643549 | R15: 7100
A16: 위엠비_개발 | B16: 개발 | C16: 수석(S) | D16: 고급 | E16: 16005 | F16: 0 | G16: =(E16-F16)/E16 -> 1 | H16: 11516 | I16: =(H16-M16)/M16 -> 0.54101432 | J16: 16005 | K16: 9500 | L16: =(J16-K16)/J16 -> 0.40643549 | M16: 7473 | N16: =(M16-R16)/R16 -> 0.33446429 | O16: 16005 | P16: 9500 | Q16: =(O16-P16)/O16 -> 0.40643549 | R16: 5600
A17: 위엠비_개발 | B17: 개발 | C17: 책임(M) | D17: 중급 | E17: 12553 | F17: 0 | G17: =(E17-F17)/E17 -> 1 | H17: 10641 | I17: =(H17-M17)/M17 -> 0.76088036 | J17: 12553 | K17: 7500 | L17: =(J17-K17)/J17 -> 0.40253326 | M17: 6043 | N17: =(M17-R17)/R17 -> 0.25895833 | O17: 12553 | P17: 7500 | Q17: =(O17-P17)/O17 -> 0.40253326 | R17: 4800
A18: 위엠비_개발 | B18: 개발 | C18: 책임(A) | D18: 초급 | E18: 10028 | F18: 0 | G18: =(E18-F18)/E18 -> 1 | H18: 10016 | I18: =(H18-M18)/M18 -> 0.98375916 | J18: 10028 | K18: 7500 | L18: =(J18-K18)/J18 -> 0.25209414 | M18: 5049 | N18: =(M18-R18)/R18 -> 0.26225 | O18: 10028 | P18: 7500 | Q18: =(O18-P18)/O18 -> 0.25209414 | R18: 4000
A19: 위엠비_개발 | B19: 개발 | C19: 사원 | D19: 초급 | E19: 10028 | F19: 0 | G19: =(E19-F19)/E19 -> 1 | H19: 9516 | I19: =(H19-M19)/M19 -> 1.2996617 | J19: 10028 | K19: 6000 | L19: =(J19-K19)/J19 -> 0.40167531 | M19: 4138 | N19: =(M19-R19)/R19 -> 0.293125 | O19: 10028 | P19: 6000 | Q19: =(O19-P19)/O19 -> 0.40167531 | R19: 3200
A20: 위엠비_개발 | C20: 평균 | F20: =SUM(F13:F19)/7 -> 0 | G20: =AVERAGE(G13:G19) -> 1 | H20: =SUM(H13:H19)/7 -> 11887.429 | I20: =(H20-M20)/M20 -> 0.38749104 | K20: =SUM(K13:K19)/7 -> 9000 | L20: =AVERAGE(L13:L19) -> 0.39244471 | M20: =SUM(M13:M19)/7 -> 8567.5714 | N20: =(M20-R20)/R20 -> 0.32977827 | P20: =SUM(P13:P19)/7 -> 9000 | Q20: =AVERAGE(Q13:Q19) -> 0.39244471 | R20: =SUM(R13:R19)/7 -> 6442.8571
A21: 외주_컨설팅 | B21: 컨_특 | C21: 이사 | D21: 특급 | E21: 25000 | F21: 0 | G21: =(E21-F21)/E21 -> 1 | H21: 11000
A22: 외주_컨설팅 | B22: 컨_고 | C22: 부장 | D22: 고급 | E22: 20000 | F22: 0 | G22: =(E22-F22)/E22 -> 1 | H22: 9000
A23: 외주_컨설팅 | B23: 컨_중 | C23: 차장 | D23: 중급 | E23: 16000 | F23: 0 | G23: =(E23-F23)/E23 -> 1 | H23: 8000
A24: 외주_컨설팅 | B24: 컨_초 | C24: 과장 | D24: 초급 | E24: 14000 | F24: 0 | G24: =(E24-F24)/E24 -> 1 | H24: 7000
A25: 외주_컨설팅 | C25: 평균
A26: 외주_개발 | B26: 개_특 | C26: 이사 | D26: 특급 | E26: 20498 | F26: 0 | G26: =(E26-F26)/E26 -> 1 | H26: 8500
A27: 외주_개발 | B27: 개_고 | C27: 차부장 | D27: 고급 | E27: 16005 | F27: 0 | G27: =(E27-F27)/E27 -> 1 | H27: 7500
A28: 외주_개발 | B28: 개_중 | C28: 과장 | D28: 중급 | E28: 12553 | F28: 0 | G28: =(E28-F28)/E28 -> 1 | H28: 6500
A29: 외주_개발 | B29: 개_초 | C29: 대리 | D29: 초급 | E29: 10028 | F29: 0 | G29: =(E29-F29)/E29 -> 1 | H29: 5500
A30: 외주_개발 | C30: 평균

Sheet 기준-경비
A1: [ 기 준 경 비 ]
G2: (단위:천원)
A3: 구분 | D3: 기준 | G3: 기준액
A4: 야근식대 | B4: 내부 | C4: 월*인 | D4: 인당 10,000/일 | E4: 10 | F4: 0 | G4: =+E4*F4 -> 0
A5: 프로젝트부서비 | B5: 내부 | C5: 월*인 | D5: 인당 25,000 | G5: 25
A6: 프로젝트부서비 | B6: 외주 | C6: 월*인 | D6: 인당 25,000 | G6: 25
A7: 워크샾 | C7: 횟수*인 | D7: 1인당 50,000, 분기당 1회 이내 | G7: 0
A8: Kick-Off비용 | C8: 횟수*인 | D8: 1인당 150,000, 시작월 및 종료월 | G8: 0
A9: 지방 임차비 | D9: 인당 50,000/일 | E9: 50 | F9: 0 | G9: =+E9*F9 -> 0
A10: 지방 출장비(월 22일 기준 일 20,000원 반영) | D10: 인당 20,000/일 | E10: 20 | F10: 3 | G10: 0
A11: 출장교통비 - 항공권,KTX,렌터카,주유비 등 | D11: 인당 100,000/일 | E11: 100 | F11: 4 | G11: 120
A12: 기타 | D12: 사무실 임대 또는 PM의 의사결정에 의한 경비
