Workbook

Sheet 예상MD산정
A1: O 예상 인력 투입 공수 (MD) | G1: O 예상 인력 투입 공수 (MM) | J1: 22
A2: 구분 | B2: 내용 | C2: 수량 | D2: 기준MD | E2: MD | G2: 구분 | H2: MD | I2: MD(난이도) | J2: MM
A3: PM | B3: PM/사업관리 | C3: 1 | E3: =C3*D3 -> 0 | G3: PM | H3: =SUMIF(A3:A23,G3,E3:E23) -> 0 | I3: =H3*난이도!E60 -> 0 | J3: 3.5 | K3: 정현우
A4: 개발 | B4: 개발 환경 구축 (서버 설치 포함) | C4: 1 | D4: 5 | E4: =C4*D4 -> 5 | G4: 개발 | H4: =SUMIF(A3:A29,G4,E3:E29) -> 150 | I4: =H4*난이도!E60 -> 156.89655 | J4: =I4/J1 -> 7.1316614 | K4: 신동민
A5: 개발 | B5: 운영 환경 구축 | C5: 1 | D5: 5 | E5: =C5*D5 -> 5 | G5: I/F | H5: =SUMIF(A3:A29,G5,E3:E29) -> 89 | I5: =H5*난이도!E60 -> 93.091954 | J5: =I5/J1 -> 4.2314525 | K5: 최진희
A6: 개발 | B6: 공통 (로그인,메뉴,권한,레이아웃 등) | C6: 1 | D6: 10 | E6: =C6*D6 -> 10 | G6: 2D디자인 | H6: =SUMIF(A3:A29,G6,E3:E29) -> 15 | I6: =H6*난이도!E60 -> 15.689655 | J6: =I6/J1 -> 0.71316614 | K6: 김령희
A7: 개발 | B7: 화면(컨텐츠 ≤ 5) 설계 (팝업 포함) | C7: 30 | D7: 2 | E7: =C7*D7 -> 60 | G7: 3D모델링 | H7: =SUMIF(A3:A29,G7,E3:E29) -> 577 | I7: =H7*'3D 모델링'!J3+'3D 모델링'!E14 -> 67.7 | J7: =I7/J1 -> 3.0772727 | K7: 추민욱
A8: 개발 | B8: 화면(컨텐츠 ≥ 5) 설계 (팝업 포함) | D8: 3 | E8: =C8*D8 -> 0 | G8: 포탈 | H8: =SUMIF(A3:A29,G8,E3:E29) -> 40 | I8: =H8*난이도!E60 -> 41.83908 | J8: =I8/J1 -> 1.9017764 | K8: 최진희
A9: 개발 | B9: 화면 개발(컨텐츠 ≤ 5) (팝업 포함) | C9: 30 | D9: 2 | E9: =C9*D9 -> 60 | G9: P&ID | H9: =SUMIF(A3:A29,G9,E3:E29) -> 50 | I9: =H9*난이도!E60 -> 52.298851 | J9: =I9/J1 -> 2.3772205 | K9: 이재형
A10: 개발 | B10: 화면 개발(컨텐츠 ≥ 5) (팝업 포함) | D10: 3 | E10: =C10*D10 -> 0 | G10: 합계 | J10: =SUM(J3:J9) -> 22.93255
A11: 개발 | B11: 3D 애니메이션 (효과,사운드) | D11: 3 | E11: =C11*D11 -> 0
A12: 개발 | B12: SOP 관리 | D12: 20 | E12: =C12*D12 -> 0
A13: 개발 | B13: 설정/보고서/통계 등 | D13: 3 | E13: =C13*D13 -> 0
A14: 개발 | B14: 메타버스 | C14: 1 | D14: 10 | E14: =C14*D14 -> 10
A15: I/F | B15: 연계시스템 (분석,설계) | C15: 10 | D15: 5 | E15: =C15*D15 -> 50
A16: I/F | B16: TIM 워커 DB to DB 등 간단 | D16: 1 | E16: =C16*D16 -> 0
A17: I/F | B17: TIM 그 외 워커 | D17: 2 | E17: =C17*D17 -> 0
A18: I/F | B18: 제품 미사용 연계 개발 | D18: 5 | E18: =C18*D18 -> 0
A19: I/F | B19: TIM+ 워크플로우 간단 | C19: 10 | D19: 2 | E19: =C19*D19 -> 20
A20: I/F | B20: TIM+ 워크플로우 복잡 | C20: 3 | D20: 3 | E20: =C20*D20 -> 9
A21: I/F | B21: DB(테이블) 설계 | C21: 20 | D21: 0.5 | E21: =C21*D21 -> 10
A22: 2D디자인 | B22: 공통 컨셉 디자인 | C22: 2 | D22: 5 | E22: =C22*D22 -> 10
A23: 2D디자인 | B23: 화면 디자인 (시안) | C23: 5 | D23: 1 | E23: =C23*D23 -> 5
A24: 3D모델링 | B24: 모델링 (건물/층/설비) | C24: - | D24: - | E24: ='3D 모델링'!E15 -> 577
A25: 포탈 | B25: 개발 환경 구축 (서버 설치 포함) | C25: 1 | D25: 5 | E25: =C25*D25 -> 5
A26: 포탈 | B26: 운영 환경 구축 | C26: 1 | D26: 5 | E26: =C26*D26 -> 5
A27: 포탈 | B27: 공통 (로그인,메뉴,권한,레이아웃 등) | C27: 1 | D27: 10 | E27: =C27*D27 -> 10
A28: 포탈 | B28: 포탈 (보고서/통계/설정) | C28: 10 | D28: 2 | E28: =C28*D28 -> 20
A29: P&ID | B29: P&ID 웹 전환 | C29: - | D29: - | E29: ='P&ID'!D10 -> 50
A30: 합계(MD) | E30: =SUM(E4:E28) -> 871

Sheet 난이도
A1: O 공통 적용
A2: 구분 | B2: 내용 | C2: 설명 | D2: 난이도 | E2: 가중치
A3: 요구사항 | B3: 요구사항 정의서 미제공 | C3: 구두/회의 중심 전달 | D3: 2
B4: 요구사항 수시 변경 예상 | C4: 스펙 Freeze 어려움 | D4: 2
B5: 고객의 IT 이해도 낮음 | C5: 기술적 소통 난이도 상승 | D5: 2
B6: 고객 의사결정자 부재 또는 다수 | C6: 승인/결정 지연 가능성 | D6: 2
A7: 화면, 기능 | B7: 화면 ≥ 20개 | C7: CRUD 중심 화면, 팝업포함 | D7: 3
B8: 업무 기능 ≥ 5개 모듈로 나눠짐 | C8: 업무 도메인 분리가 뚜렷함 | D8: 1
B9: 사용자 정의 기능 많음 | C9: 워크플로우, 조건부 입력 등 | D9: 3
B10: 권한, 조직별 접근 제한 포함 | C10: Role-based UI 구성 필요 | D10: 2
B11: 배치 프로세스 포함 | C11: 예약 실행, 로그처리 등 필요 | D11: 2
B12: 반응형 지원 | C12: 반응형 지원 개발 필요 | D12: 3
B13: UI/접근성 | C13: 모바일 지원 포함 (앱,웹앱) | D13: 3
A14: 연계 및 외부 시스템 | B14: 외부 시스템 연계 ≥ 5개 | C14: API, DB 연동 등 | D14: 1
B15: 실시간 연계 포함 | C15: Webhook, Event 등 | D15: 2
B16: 레거시 시스템 연계 | C16: 명세 미비, 파악 난이도 ↑ | D16: 2
B17: 인증/SSO 연동 포함 | C17: AD, OAuth 등 | D17: 3
A18: 데이터 및 보고서 | B18: 정형 보고서 ≥ 20건 | C18: PDF/Excel 출력 등 | D18: 1
B19: 대용량 데이터 처리 | C19: 100만건 이상 | D19: 2
B20: 마이그레이션 포함 | C20: 데이터 정제/이관 | D20: 0
B21: 정합성 검증 포함 | C21: 정확도 중요 | D21: 2
A22: 기술 환경 | B22: 클라우드 환경 구축 | C22: AWS, Azure 등 | D22: 3
B23: Hybrid 인프라 | C23: 온프 + 클라우드 병행 | D23: 0
B24: 신규 기술 도입 | C24: AI, IoT, GIS 등 | D24: 0
B25: 복잡한 DB (30테이블 이상) | C25: 관계 정규화 + 성능 고려 | D25: 2
A26: 보안 및 인증 | B26: 사용자 권한 분기 3단계 이상 | C26: 화면별 권한 설정 필수 | D26: 2
B27: 데이터 암호화 필요 | C27: 전송/저장 모두 포함 | D27: 2
B28: 공공기관 보안규격 준수 | C28: ISMS, CC 등 인증 요건 있음 | D28: 3
A29: 운영/인력관리 | B29: 납기 ≤ 2개월 | C29: 기간 촉박 | D29: 0
B30: 프로젝트 기간 ≥ 12개월 | C30: 장기 인력 유지/교체 이슈 | D30: 3
B31: 병행 프로젝트 존재 | C31: 일정/자원 집중 어려움 | D31: 3
B32: 개발 서버 운영 | C32: 운영서버 직접 반영은 어려움 | D32: 1
B33: 고객 내부 승인 절차 복잡 | C33: 화면마다 승인 필요 | D33: 1
B34: 주 단위 납품 일정 요구 | C34: 세분화된 일정 관리 필요 | D34: 2
B35: 고객사 상주 필수 | C35: 피로도, 업무 밀도, 팀 운영 난이도 ↑ | D35: 2
B36: 상주 위치 원거리 | C36: 출장, 교통, 숙소 등 추가 리스크 | D36: 3
B37: 외주 인력과의 협업 필수 | C37: SI 협력사, 고객 IT팀, 프리랜서 등 협조 필요 | D37: 3
B38: 인력 교체 가능성 있음 (예: 6개월 계약) | C38: 인수인계 등 중간 공백 위험 존재 | D38: 2
B39: 고객 내부 정치적 이슈 있음 | C39: 팀 변경 등 승인 구조 변경 | D39: 2
A40: 감리 | B40: 감리 대상 프로젝트, 공공산출물 | C40: 일정금액 이상 또는 공공과제 | D40: 3
...

Sheet 3D 모델링
A1: O 3D 모델링(배치 포함) 공수 기준표 | H1: O MD산정 가중치
A2: 구분 | B2: 난이도 | C2: 수량 | D2: 기준MD | E2: 산정MD | F2: 비고 | H2: 항목 | I2: 내용 | J2: 가중치 | L2: 내용 | M2: 가중치 | N2: 설명
A3: 부지 | B3: - | C3: 1 | D3: 1 | E3: 2 | F3: 대형 복합건물, 곡면/비정형 파사드 | H3: 3D 입력 자료 | I3: 모델링 제공 | J3: =VLOOKUP(I3,L3:M7,2,0) -> 0.1 | L3: 모델링 제공 | M3: 0.1 | N3: 배치 등
A4: 건물 | B4: 상 | D4: 1 | E4: =C4*D4 -> 0 | F4: 대형 복합건물, 곡면/비정형 파사드 | L4: CAD 도면 제공 | M4: 1 | N4: DWG/IFC 등 정합성 양호
B5: 중 | C5: 30 | D5: 0.5 | E5: =C5*D5 -> 15 | F5: 중고층 건물, 입면 구성 다양 | L5: CAD 일부 + 사진 병행 | M5: 1.15 | N5: 누락 도면 보완 필요
B6: 하 | D6: 0.3 | E6: =C6*D6 -> 0 | F6: 단층 건물, 구성요소 적음, 대칭구조 | L6: 사진/실측 제공 | M6: 1.3 | N6: 3D 모델링을 사진 기반 추정
A7: 층 | B7: 상 | D7: 0.5 | E7: =C7*D7 -> 0 | F7: 바닥 단차, 복잡 평면 구조 | L7: 실측 필요 | M7: 1.5 | N7: 현장 실측 → 모델화
B8: 중 | C8: 100 | D8: 0.3 | E8: =C8*D8 -> 30 | F8: 다소 복잡한 평면 구조
B9: 하 | D9: 0.2 | E9: =C9*D9 -> 0 | F9: 단순한 평면구조
A10: 설비/장비 | B10: 상 | D10: 2 | E10: =C10*D10 -> 0 | F10: 중대형 설비, 배관등 구조 복잡(보일러, 터빈 등)
B11: 중 | C11: 1000 | D11: 0.5 | E11: =C11*D11 -> 500 | F11: 중형 설비
B12: 하 | D12: 0.2 | E12: =C12*D12 -> 0 | F12: 박스 형태, 디테일 적음
B13: 중복 | C13: 300 | D13: 0.1 | E13: =C13*D13 -> 30 | F13: 중복 사용 (배치 필요)
A14: 캐릭터 | B14: - | C14: 2 | D14: 5 | E14: =C14*D14 -> 10 | F14: 메타버스
A15: 합계 (MD) | E15: =SUM(E3:E13) -> 577
A16: MM | E16: =E15/22 -> 26.227273

Sheet P&ID
A1: O P&ID 공수 기준표 | G1: O MD산정 가중치
E2: P&ID 논의 후 (웹전환수량에 따른 금액산정 필요, 30만?)
A4: 구분 | B4: 수량 | C4: 기준MD | D4: 산정MD | E4: 비고 | G4: 항목 | H4: 내용 | I4: 가중치 | K4: 내용 | L4: 가중치 | M4: 설명
A5: P&ID | B5: 500 | C5: 1 | D5: =B5*C5 -> 500 | G5: 전환 방식 | H5: MS Visio DB | I5: =VLOOKUP(H5,K5:L9,2,0) -> 0.1 | K5: 수기 작성 | L5: 1
A6: SLD | C6: 0.5 | D6: =B6*C6 -> 0 | K6: DrawDX | L6: 0.15
D7: =B7*C7 -> 0 | K7: MS Visio DB | L7: 0.1
D8: =B8*C8 -> 0
D9: =B9*C9 -> 0
A10: 합계 (MD) | D10: =SUM(D5:D9)*I5 -> 50
A11: MM | D11: =D10/22 -> 2.2727273
