Workbook

Sheet 사업 종합 난이도 평가
B2: 프로젝트 명 : 현대제철 AI-Safeguard 통합관제 SW 구축 추가 개발
B4: 사업 난이도 종합 평가
F5: 각탭의 결과를 반영한것으로 수정하지 마세요
B6: No | C6: 항목 | D6: 점수(1-10) | E6: 가중치 | F6: 결과 점수 | I6: 난이도 해석
B7: 1 | C7: 기술적 난이도 | D7: =F30 -> 3.2 | E7: 0.3 | F7: =D7*E7 -> 0.96 | I7: 1 | J7: RISK 낮음
B8: 2 | C8: 요구사항의 복잡성 | D8: =F43 -> 3.1 | E8: 0.25 | F8: =D8*E8 -> 0.775 | I8: 3 | J8: 낮음
B9: 3 | C9: 프로젝트 팀 구성 | D9: =F54 -> 3.55 | E9: 0.2 | F9: =D9*E9 -> 0.71 | I9: 4 | J9: 중간
B10: 4 | C10: 프로젝트 관리 요소 | D10: =F66 -> 3.15 | E10: 0.15 | F10: =D10*E10 -> 0.4725 | I10: 6 | J10: 높음
B11: 5 | C11: 외부 의존성 | D11: =F76 -> 3.2 | E11: 0.1 | F11: =D11*E11 -> 0.32 | I11: 8 | J11: 매우높음
B12: 총합 | D12: =SUM(D7:D11) -> 16.2 | E12: =SUM(E7:E11) -> 1 | F12: =SUM(F7:F11) -> 3.2375
B14: 종합 의견
B15: 내용 작성
B18: 1.기술적 난이도 | F18: 각탭의 결과를 반영한것으로 수정하지 마세요
B19: No | C19: 항목 | D19: 점수(1-10) | E19: 가중치 | F19: 결과 점수
B20: 1 | C20: 기술 스택 | D20: ='1.기술적난이도'!C4 -> 2 | E20: 0.1 | F20: =D20*E20 -> 0.2
B21: 2 | C21: 아키텍처 | D21: ='1.기술적난이도'!C5 -> 2 | E21: 0.1 | F21: =D21*E21 -> 0.2
B22: 3 | C22: 데이터 관리 | D22: ='1.기술적난이도'!C6 -> 4 | E22: 0.1 | F22: =D22*E22 -> 0.4
B23: 4 | C23: 보안 | D23: ='1.기술적난이도'!C7 -> 3 | E23: 0.1 | F23: =D23*E23 -> 0.3
B24: 5 | C24: 성능 | D24: ='1.기술적난이도'!C8 -> 5 | E24: 0.1 | F24: =D24*E24 -> 0.5
B25: 6 | C25: 시스템 통합 | D25: ='1.기술적난이도'!C9 -> 2 | E25: 0.1 | F25: =D25*E25 -> 0.2
B26: 7 | C26: 개발 및 운영 환경 | D26: ='1.기술적난이도'!C10 -> 5 | E26: 0.1 | F26: =D26*E26 -> 0.5
B27: 8 | C27: 테스트 및 품질 보증 | D27: ='1.기술적난이도'!C11 -> 3 | E27: 0.1 | F27: =D27*E27 -> 0.3
B28: 9 | C28: 배포 및 운영 | D28: ='1.기술적난이도'!C12 -> 3 | E28: 0.1 | F28: =D28*E28 -> 0.3
B29: 10 | C29: 기술적 리스크 | D29: ='1.기술적난이도'!C13 -> 3 | E29: 0.1 | F29: =D29*E29 -> 0.3
B30: 총합 | D30: =SUM(D20:D29) -> 32 | E30: =SUM(E20:E29) -> 1 | F30: =SUM(F20:F29) -> 3.2
B32: 2.요구사항 복잡성 | F32: 각탭의 결과를 반영한것으로 수정하지 마세요
B33: No | C33: 항목 | D33: 점수(1-10) | E33: 가중치 | F33: 결과 점수
B34: 1 | C34: 기능 및 범위 | D34: ='2.요구사항복잡성'!C4 -> 3 | E34: 0.15 | F34: =D34*E34 -> 0.45
B35: 2 | C35: 요구사항의 명확성 | D35: ='2.요구사항복잡성'!C5 -> 3 | E35: 0.15 | F35: =D35*E35 -> 0.45
B36: 3 | C36: 이해관계자 복잡성 | D36: ='2.요구사항복잡성'!C6 -> 3 | E36: 0.1 | F36: =D36*E36 -> 0.3
B37: 4 | C37: 사용자 및 사용 시나리오 | D37: ='2.요구사항복잡성'!C7 -> 2 | E37: 0.1 | F37: =D37*E37 -> 0.2
B38: 5 | C38: 데이터 및 비즈니스 로직 | D38: ='2.요구사항복잡성'!C8 -> 3 | E38: 0.1 | F38: =D38*E38 -> 0.3
B39: 6 | C39: 성능 및 확장성 | D39: ='2.요구사항복잡성'!C9 -> 5 | E39: 0.1 | F39: =D39*E39 -> 0.5
B40: 7 | C40: 보안 및 규정 준수 | D40: ='2.요구사항복잡성'!C10 -> 3 | E40: 0.1 | F40: =D40*E40 -> 0.3
B41: 8 | C41: 시스템 연계 | D41: ='2.요구사항복잡성'!C11 -> 4 | E41: 0.1 | F41: =D41*E41 -> 0.4
B42: 9 | C42: 긴급도 | D42: ='2.요구사항복잡성'!C12 -> 2 | E42: 0.1 | F42: =D42*E42 -> 0.2
B43: 총합 | D43: =SUM(D34:D42) -> 28 | E43: =SUM(E34:E42) -> 1 | F43: =SUM(F34:F42) -> 3.1
B45: 3.프로젝트 팀 구성 | F45: 각탭의 결과를 반영한것으로 수정하지 마세요
B46: No | C46: 항목 | D46: 점수(1-10) | E46: 가중치 | F46: 결과 점수
B47: 1 | C47: 기술 숙련도 | D47: ='3.프로젝트팀구성'!C4 -> 4 | E47: 0.2 | F47: =D47*E47 -> 0.8
...

Sheet 1.기술적난이도
A1: 1. 기술적 난이도 체크 항목
A3: No | B3: 항목 | C3: 점수(1-10) | D3: 가중치 | E3: 결과 점수 | G3: 1. 기술 스택 | H3: ▣ 프로젝트에서 사용될 기술이나 프레임워크 신규 여부
A4: 1 | B4: 기술 스택 | C4: 2 | D4: 0.1 | E4: =C4*D4 -> 0.2 | H4: ▣ 기존에 사용 중인 기술과 호환성 및 재사용 가능 여부
A5: 2 | B5: 아키텍처 | C5: 2 | D5: 0.1 | E5: =C5*D5 -> 0.2 | H5: ▣ 학습 커브가 있는 새로운 기술에 대한 고려 필요 여부
A6: 3 | B6: 데이터 구축 | C6: 4 | D6: 0.1 | E6: =C6*D6 -> 0.4 | F6: UCMDB | H6: ▣ 기술에 대한 표준화, 상세화, 레퍼런스 보유 여부
A7: 4 | B7: 보안 | C7: 3 | D7: 0.1 | E7: =C7*D7 -> 0.3 | F7: 취약점 | G7: 2. 아키텍처 | H7: ▣ 프로젝트는 아키텍처의 복잡성(고가용성 고려, 대용량 처리, MSA 등 고려 여부)
A8: 5 | B8: 성능 | C8: 5 | D8: 0.1 | E8: =C8*D8 -> 0.5 | H8: ▣ 아키텍처 설계 및 구현의 잠재적인 리스크 여부
A9: 6 | B9: 시스템 통합 | C9: 2 | D9: 0.1 | E9: =C9*D9 -> 0.2 | H9: ▣ 분산 시스템의 설계 또는 클라우드 기반 환경의 구축 등 고려 요구가 있는지 여부
A10: 7 | B10: 개발 및 운영 환경 | C10: 5 | D10: 0.1 | E10: =C10*D10 -> 0.5 | H10: ▣ 시스템 간의 상호작용(인터페이스, API 통합)의 복잡성이 있는지 여부
A11: 8 | B11: 테스트 및 품질 보증 | C11: 3 | D11: 0.1 | E11: =C11*D11 -> 0.3 | G11: 3. 데이터 구축 | H11: ▣ 표준 데이터 모델을 사용해도 되는지, 복잡한 추가적 설계가 많은지 여부
A12: 9 | B12: 배포 및 운영 | C12: 3 | D12: 0.1 | E12: =C12*D12 -> 0.3 | H12: ▣ 대규모 데이터 처리(예: 빅데이터, 실시간 처리)를 고려한 설계가 되어야 하는지 여부
A13: 10 | B13: 기술적 리스크 | C13: 3 | D13: 0.1 | E13: =C13*D13 -> 0.3 | H13: ▣ 데이터의 정합성과 일관성, 개인정보보호를 위한 암호화 처리 필요 여부
A14: 총합 | C14: =SUM(C4:C13) -> 32 | D14: =SUM(D4:D13) -> 1 | E14: =SUM(E4:E13) -> 3.2 | H14: ▣ 기존 데이터 마이그레이션 여부(마이그레이션 복잡성, 첨부파일 포함여부)
G15: 4. 보안 | H15: ▣ 일반 보안 사항이 아닌 별도의 기술 접목이 필요한지 여부 (AD, SSO, 2단계 인증 등)
A16: 활용 방법 | H16: ▣ 보안 요구사항(예: 암호화, 인증, 권한 관리 등)의 복잡성, 추가 요구사항 여부
A17: 각 항목에 대해 점수화 (예: 1~10)하여 평가합니다. | H17: ▣ 데이터 및 시스템에 대한 보안성 검토 요구사항 여부(웹취약점, 시큐어코딩 등)
A18: 항목별로 가중치를 부여하여 기술적 난이도의 총점을 계산합니다. | G18: 5. 성능 | H18: ▣ 초당 처리량(TPS), 응답 시간, 가용성 등 성능 요구사항 고려 필요 여부
A19: 점수에 따라 적절한 리스크 관리 계획 및 추가 리소스 할당을 고려합니다. | H19: ▣ 고가용성(HA) 및 확장성(Scalability)을 위한 설계 여부
H20: ▣ 성능 테스트와 최적화에 대한 요구사항이 존재하고 대응할 수 있는 수준인지 여부
A21: 위 체크리스트는 프로젝트의 복잡성과 특성에 따라 세부적으로 조정하여 사용할 수 있습니다. | G21: 6. 시스템 통합 | H21: ▣ 시스템 통합(연계) 대상이 많은지 여부(15개 이상의 연계대상 유무)
H22: ▣ 레거시 시스템과 업무절차의 연계가 필요한지 여부(프로세스, 태그매핑, SOP등)
H23: ▣ 시스템 간의 데이터 변환이나 실시간 동기화등 데이터 처리 요건이 있는지 여부
G24: 7. 개발 및 운영 환경 | H24: ▣ 개발시스템, 테스트시스템, 운영시스템의 구분이 명확하고 프로세스 준수 여부
H25: ▣ 웹 호환성, 시스템 운영체제 호환성, 웹표준 등 다양한 환경을 지원하여야 하는지 여부
H26: ▣ 운영 환경이 새로운 시스템 구축인지, 기존 시스템에 반영해야 하는지, 서비스의 위험성
G27: 8. 테스트 및 품질 보증 | H27: ▣ 단위테스트, 통합테스트, 사용자 테스트, 성능 테스트 등 까다로운 테스트 절차 진행 여부
H28: ▣ 품질보증 활동을 요구하고 난위도 높은 품질 요구사항이 있는가?(예외처리, 에러로그, 팝업)
H29: ▣ 테스트 케이스가 복잡하고 다양하며, QA의 투입 필요성이 있는 프로젝트인지 여부
G30: 9. 배포 및 운영 | H30: ▣ 배포 프로세스의 복잡성이 있는지 여부 (배포일정, 무중단, 서비스 중요도여부)
H31: ▣ 모니터링 및 로깅 시스템의 구축이 필요 여부
H32: ▣ 시스템 사용자 수가 많아서 운영 지원이 매우 빠르게 요구되고 다양하고 많은지 여부
G33: 10. 기술적 리스크 | H33: ▣ 솔루션의 성숙도, 기술 성숙도를 고려하여 프로젝트의 잠재적 리스크 여부
H34: ▣ 솔루션의 지원 범위가 매우 한정적인가, 추가 커스터마이징 및 R&D 개발이 필요한지 여부
H35: ▣ 기술 도메인에 따라 많은 영향을 줄 수 있는 사업인지 여부(도메인 이해도, 외부 기술 의존)

Sheet 2.요구사항복잡성
A1: 2. 요구사항의 복잡성 체크 항목
A3: No | B3: 항목 | C3: 점수(1-10) | D3: 가중치 | E3: 결과 점수 | G3: 1. 기능 및 범위 | H3: ▣ 기능 요구사항의 수와 다양성, 비기능 요구사항의 어려움이 많이 존재하는지 여부
A4: 1 | B4: 기능 및 범위 | C4: 3 | D4: 0.15 | E4: =C4*D4 -> 0.45 | H4: ▣ 기능 및 범위가 명확하게 파악할 수 있는지 여부(RFP 유무, 불명확 정도, 잠재적 범위 고려)
A5: 2 | B5: 요구사항의 명확성 | C5: 3 | D5: 0.15 | E5: =C5*D5 -> 0.45 | H5: ▣ 주요 기능 하위에 세분화된 기능들이 많이 존재하는 프로젝트 인가?(숨겨진 기능이 예상되는지)
A6: 3 | B6: 이해관계자 복잡성 | C6: 3 | D6: 0.1 | E6: =C6*D6 -> 0.3 | H6: ▣ 시스템 통합, 마이그레이션, 테스트, 컨설팅 등 구축 범위가 2개 이상 영역에 포함되는지 여부
A7: 4 | B7: 사용자 및 사용 시나리오 | C7: 2 | D7: 0.1 | E7: =C7*D7 -> 0.2 | G7: 2. 요구사항의 명확성 | H7: ▣ 요구사항이 비교적 명확하게 정의되어 제시되었는지 여부
A8: 5 | B8: 데이터 및 비즈니스 로직 | C8: 3 | D8: 0.1 | E8: =C8*D8 -> 0.3 | H8: ▣ 체계적의 RFP가 구성되었거나, 사전에 Presale가 되어 RFP를 제시 하였는지 여부
A9: 6 | B9: 성능 및 확장성 | C9: 5 | D9: 0.1 | E9: =C9*D9 -> 0.5 | H9: ▣ 요구사항이 명확하지 않거나, 방향성이 수립되지 않을 만한 요구사항이 얼마나 많은지 여부
A10: 7 | B10: 보안 및 규정 준수 | C10: 3 | D10: 0.1 | E10: =C10*D10 -> 0.3 | G10: 3. 이해관계자 복잡성 | H10: ▣ 요구사항 도출 및 정의를 위한 다양한 조직, 사용자, 이해관계자 유무
A11: 8 | B11: 시스템 연계 | C11: 4 | D11: 0.1 | E11: =C11*D11 -> 0.4 | H11: ▣ 사용자가 테스트 혹은 사용하면서 추가적인 요구사항이 발생할 수 있는 프로젝트 인지 여부
A12: 9 | B12: 긴급도 | C12: 2 | D12: 0.1 | E12: =C12*D12 -> 0.2 | H12: ▣ 사업을 추진하는 고객 조직의 유무, 주사업자 및 사업관리에 따른 대응 어려움, 대규모 프로젝트 참여 여부
A13: 총합 | C13: =SUM(C4:C12) -> 28 | D13: =SUM(D4:D12) -> 1 | E13: =SUM(E4:E12) -> 3.1 | G13: 4. 사용자 및 사용 시나리오 | H13: ▣ 예상되는 사용자 수가 많고, 조직이 광범위 한지 여부
H14: ▣ 다수의 절차, 사용자 시나리오를 정의하거나 동적 절차, 다양한 기기를 사용에 지원 필요 여부
H15: ▣ 사용자 인터페이스(UI)와 사용자 경험(UX)에 대한 요구사항이 복잡한지 여부
G16: 5. 데이터 및 비즈니스 로직 | H16: ▣ 데이터 처리 및 저장 요구사항이 복잡하고 다양한지 여부
H17: ▣ 시스템이 복잡한 로직을 포함하여 설계되어야 하는지 여부(계산 로직 복잡, 복합 알고리즘, 업무규칙수의 개수, 예외 처리, 조건부 분기)
H18: ▣ 데이터 수집, 처리, 저장, 제공 등 데이터와 로직의 구현이 어려운지 여부(데이터 변환, 실시간 처리, 배치 처리, 데이터 검증 규칙)
G19: 6. 성능 및 확장성 | H19: ▣ 성능 요구사항이 존재하며, 그 수준이 높은지 여부 (Response Time, 부하테스트 고려 등)
H20: ▣ 요구사항이 확장성을 고려해야 하는지 여부(멀티태넌시, 시스템 확장, 아키텍처 고려 등)
G21: 7. 보안 및 규정 준수 | H21: ▣ 보안 요구사항을 위하여 추가적인 기술 도입이나 개발이 필요한지 여부
H22: ▣ 보안 요구사항이 매우 까다로운 사업이고 사업수행을 위한 보안 관리가 철저한지 여부(프로젝트 환경구성, 자료반출 어려움, 출입관리 등)
G23: 8. 시스템 연계 | H23: ▣ 시스템 연계 요구사항에 대응하기 위한 기술이 엣지(센서, 게이트웨이)단을 고려해야 하고 프로토콜이나 연계 방안이 복잡한지 여부
H24: ▣ 외부 시스템의 연계 시 대응할 수 있는 지원 조직의 유무, 연계를 위해 분석, 설계 및 개발이 많이 소요될 가능성이 있는지 여부
G25: 9. 긴급도 | H25: ▣ 요구사항 중 빠르게 사전 구축 되거나 빠르게 수행되어야 프로젝트 진행이 수월할 수 있는 요구사항이 있는지 여부
H26: ▣ 프로젝트의 구축 일정이 매우 부족하거나 긴급도를 요구하고 있는지 여부
H27: ▣ 애자일 개발 방법론을 요구하거나 잦은 오픈일정을 요구하여 다수의 시스템 반영과 테스트가 반복될 수 있는지 여부

Sheet 3.프로젝트팀구성
A1: 3. 프로젝트 팀 구성 난이도 체크 항목
A3: No | B3: 항목 | C3: 점수(1-10) | D3: 가중치 | E3: 결과 점수 | G3: 1. 팀원의 기술 숙련도 | H3: ▣ 프로젝트에서 요구되는 기술 스택에 대한 숙련도
A4: 1 | B4: 기술 숙련도 | C4: 4 | D4: 0.2 | E4: =C4*D4 -> 0.8 | H4: • 관련 기술/프레임워크 사용 경험이 있는 팀원의 비율
A5: 2 | B5: 도메인 지식 | C5: 5 | D5: 0.15 | E5: =C5*D5 -> 0.75 | H5: • 새로운 기술 학습이 필요한 팀원의 수
A6: 3 | B6: 경험 | C6: 3 | D6: 0.15 | E6: =C6*D6 -> 0.45 | H6: ▣ 전문 기술을 가진 인력의 확보 여부
A7: 4 | B7: 인력 가용성 | C7: 3 | D7: 0.15 | E7: =C7*D7 -> 0.45 | G7: 2. 팀원의 도메인 지식 | H7: ▣ 프로젝트가 다루는 도메인(예: 금융, 의료, 제조)에 대한 이해도
A8: 5 | B8: PM의 경험 | C8: 4 | D8: 0.2 | E8: =C8*D8 -> 0.8 | H8: ▣ 관련 산업 프로젝트 경험 여부
A9: 6 | B9: 외부 인력 리스크 | C9: 2 | D9: 0.1 | E9: =C9*D9 -> 0.2 | G9: 3. 팀 구성원의 경험 | H9: ▣ 이전 유사 프로젝트 경험이 있는 팀원의 수
A10: 7 | B10: 리스크 요소 | C10: 2 | D10: 0.05 | E10: =C10*D10 -> 0.1 | H10: ▣ 프로젝트 관리 경험(예: 팀 리드, PM 등)을 가진 인력의 유무
A11: 총합 | C11: =SUM(C4:C10) -> 23 | D11: =SUM(D4:D10) -> 1 | E11: =SUM(E4:E10) -> 3.55 | H11: ▣ 신입 개발자와 숙련된 개발자 간의 균형
G12: 4. 인력 가용성 | H12: ▣ 프로젝트 팀 구성을 위한 가용인력의 유무
H13: ▣ 구성된 프로젝트 팀의 업무 중복성
H14: ▣ 프로젝트 기술 리더의 유무, 대체 가능 인력 유무
G15: 5. PM의 경험 | H15: ▣ 팀원 간의 커뮤니케이션 스킬과 협업 경험
H16: ▣ 프로젝트 고객 대응 경험
H17: ▣ 다양한 부서 및 외부 협력 업체와의 조율 능력
G18: 6. 외부 인력 리스크 | H18: ▣ 외주 인력이나 컨설팅 업체의 의존성이 높은지 여부
H19: ▣ 외부 협력 인력의 기술 적합성과 협력 난이도
G20: 7. 리스크 요소 평가 | H20: ▣ 팀원의 이탈 가능성(퇴사, 병가 등)
H21: ▣ 주요 인력에 대한 의존도와 대체 계획의 유무
H22: ▣ 기존 팀 내 갈등 또는 새로운 팀원 간의 갈등 가능성
A23: 난이도 해석
A24: 1.0~3.0 매우낮음 | C24: 팀 구성에 전혀 문제가 없으며, 프로젝트 수행이 매우 원활할 것으로 예상됨.
A25: 3.1~5.0 낮음 | C25: 소규모의 문제나 약간의 조정이 필요하지만, 대부분 원활한 진행이 가능.
A26: 5.1~7.0 보통 | C26: 일부 어려움이 예상되며, 팀원들의 추가 조정이나 교육이 필요할 수 있음.
A27: 7.1~8.5 높음 | C27: 팀 구성의 여러 측면에서 도전 과제가 존재하며, 리스크 관리 및 추가 자원 투입이 필요.
A28: 8.6~10.0 매우 높음 | C28: 팀 구성에서 심각한 문제가 예상되며, 성공적인 프로젝트 수행을 위해 대대적인 개선이 필요.

Sheet 4.프로젝트관리
A1: 4. 프로젝트 관리 난이도 체크 항목
A3: No | B3: 항목 | C3: 점수(1-10) | D3: 가중치 | E3: 결과 점수 | G3: 1. 일정 관리 | H3: ▣ 프로젝트 수행 일정이 충분히 확보되었는지 여부
A4: 1 | B4: 일정 관리 | C4: 3 | D4: 0.2 | E4: =C4*D4 -> 0.6 | H4: ▣ 주요 단계별 일정과 목표가 충분히 설정될 수 있는지 여부
A5: 2 | B5: 리소스 관리 | C5: 3 | D5: 0.15 | E5: =C5*D5 -> 0.45 | H5: ▣ 일정이 장기간으로 진행되어 명확하지 않은지 여부
A6: 3 | B6: 리스크 관리 | C6: 4 | D6: 0.1 | E6: =C6*D6 -> 0.4 | H6: ▣ 빠른 일정으로 반드시 수행해야 하는지 여부
A7: 4 | B7: 이해관계자 관리 | C7: 2 | D7: 0.1 | E7: =C7*D7 -> 0.2 | G7: 2. 리소스 관리 | H7: ▣ 프로젝트 투입 공수가 충분히 확보되고 진행에 이슈가 없는지 여부
A8: 5 | B8: 품질 관리 | C8: 5 | D8: 0.1 | E8: =C8*D8 -> 0.5 | H8: ▣ 가용한 인력의 투입이 확정되어 있는지 여부
A9: 6 | B9: 의존성관리 | C9: 4 | D9: 0.15 | E9: =C9*D9 -> 0.6 | H9: ▣ 초기 PM이 확정되어 사업을 설계하고 진행하였는지 여부
A10: 7 | B10: 변화 관리 | C10: 2 | D10: 0.1 | E10: =C10*D10 -> 0.2 | H10: ▣ 외부 업체 및 외주의 사용으로 인력에 대한 불확실성이 높은지 여부
A11: 8 | B11: 기타 요소 | C11: 2 | D11: 0.1 | E11: =C11*D11 -> 0.2 | G11: 3. 리스크 관리 | H11: ▣ 프로젝트 진행에 따른 예상 리스크가 식별될 수 있는지 여부
A12: 총합 | C12: =SUM(C4:C11) -> 25 | D12: =SUM(D4:D11) -> 1 | E12: =SUM(E4:E11) -> 3.15 | H12: ▣ 리스크에 대한 대비책이 마련되어 있는지 여부
H13: ▣ 기술적 불확실성이 높은 요구 기능이 있는지 여부
B14: 난이도 해석 | H14: ▣ 프로젝트 범위의 불명확성, 변경 가능성이 높은지 여부
B15: 1.0~3.0 : 매우 낮음 - 거의 고려할 필요가 없음. | G15: 4. 이해관계자 관리 | H15: ▣ 이해관계자가 식별되어 있거나, 수행사와의 교류가 높은지 여부
B16: 3.1~5.0 : 낮음 - 약간의 관리가 필요함. | H16: ▣ 이해관계자와 커뮤니케이션이 비교적 수월한지 여부
B17: 5.1~7.0: 보통 - 일정 수준의 주의와 관리가 필요함. | H17: ▣ 빠른 의사결정을 진행하기 위한 조직(TFT), 담당자가 있는지 여부
B18: 7.1~9.0: 높음 - 집중적인 관리가 필요함. | H18: ▣ 고객의 기대치에 따라, 기술적/영업적 대응이 가능한지 여부
B19: 9.1~10.0: 매우 높음 - 매우 어려운 요소이며 고도의 주의가 필요함. | G19: 5. 품질 관리 | H19: ▣ 프로젝트 품질 요구사항이 명확한지 여부(산출물 등)
H20: ▣ 고객의 테스트 환경 구성, 테스트 검증을 위한 절차가 명확하고 현실적으로 대응할 수 있는지 여부
H21: ▣ 감리(내부/외부 감리), 감사, 테스트 조직 등 품질을 검토하는 조직이 존재하여 심도있는 대응이 필요한지 여부
G22: 6. 의존성 관리 | H22: ▣ 프로젝트 내부, 수행사 내부 조직간 서로 협업이 많이 이루어져야 하는지 여부
H23: ▣ 프로젝트가 외부 시스템, 공급업체, 외주 인력 등 의존성이 높은지 여부
G24: 7. 변화 관리 | H24: ▣ 프로젝트로 인해 고객사의 조직, 업무체계, 절차 등 신규 혹은 변경이 요구되는지 여부
H25: ▣ 시스템 혹은 기능, 업무 절차 등이 지속적으로 현행화되거나 관리되어야 하는지 여부
G26: 8. 기타 요소 | H26: ▣ 법적/규제 요건: 프로젝트에 적용되는 규제나 법적 요구사항에 따라 관리의 복잡성이 있는지 여부
H27: ▣ 표준 준수, 보안 준수에 따른 관리요소가 많이 존재 여부
H28: ▣ 사업관리가 필요하며, 프로젝트 규모와 관리적 요소가 많은 사업인지 여부

Sheet 5.외부의존성
A1: 5. 외부 의존성 관리 난이도 체크 항목
A3: No | B3: 항목 | C3: 점수(1-10) | D3: 가중치 | E3: 결과 점수 | G3: 1. 사업 구조의 위험성 | H3: ▣ 타 기업이 주사업자로 효과적인 수행이 가능한지 여부, 위험도가 높은지 여부
A4: 1 | B4: 사업 구조의 위험성 | C4: 3 | D4: 0.3 | E4: =C4*D4 -> 0.9 | H4: ▣ 컨소시엄의 복잡성으로 의사소통의 어려움, 협업의 복잡성, 리스크 가능성이 있는지 여부
A5: 2 | B5: 도메인 지식 | C5: 3 | D5: 0.15 | E5: =C5*D5 -> 0.45 | H5: ▣ 단일 구조로 수행하지만 협력업체의 필요성 혹은 기술적 리스크가 존재하는지 여부
A6: 3 | B6: 외부 공급자의 신뢰도 | C6: 3 | D6: 0.15 | E6: =C6*D6 -> 0.45 | H6: ▣ 대규모 사업으로 일부 영역을 담당하지만 다양한 관리 요소 및 제약, 커뮤니케이션 복잡성 여부
A7: 4 | B7: 기술적 통합 난이도 | C7: 3 | D7: 0.2 | E7: =C7*D7 -> 0.6 | G7: 2. 도메인 지식 | H7: ▣ 외부 도메인 지식과 기술을 적용하여 신규 시스템을 구축하는지 여부
A8: 5 | B8: 유지보수 용이성 | C8: 4 | D8: 0.1 | E8: =C8*D8 -> 0.4 | H8: ▣ 경험하지 못한 새로운 영역의 전문성을 가진 업체의 데이터와 기술을 적용 하는지 여부
A9: 6 | B9: 사업 비용 및 검수 | C9: 4 | D9: 0.1 | E9: =C9*D9 -> 0.4 | H9: ▣ 타 솔루션과 통합적인 비즈니스 모델로 시스템을 구축하는지 여부(Embeded, 모듈화 등)
A10: 총합 | D10: =SUM(D3:D9) -> 1 | E10: =SUM(E4:E9) -> 3.2 | G10: 3. 외부 공급자의 신뢰도 | H10: ▣ 외부 협력업체의 기업 안정성에 리스크 여부
H11: ▣ 명확한 업무 범위 구분과 R&R 수립 가능 여부
H12: ▣ 외부 공급자의 협업 경험이 많은지 여부
G13: 4. 기술적 통합 난이도 | H13: ▣ 기술 통합의 복잡성이 높으며, 다양한 요구사항 커스터마이징 필요 여부
B14: 난이도 해석 | H14: ▣ 사전 테스트 또는 협업을 통한 기술적 접근이 용이한지 여부
B15: 1.0~3.0 : 매우 낮음 - 리스크 및 관리 필요성이 거의 없음. | H15: ▣ 통합에 따른 아키텍처 변경, 추가적인 고려사항, 이슈가 많이 존재하는지 여부
B16: 3.1~5.0 : 낮음 - 관리가 필요하지만 리스크가 낮고 통제가 쉬움. | G16: 5. 유지보수 용이성 | H16: ▣ 외부에 의존하지 않고 유지보수를 수행할 수 있는지 여부
B17: 5.1~7.0 : 보통 - 일부 리스크가 존재하며 관리가 필요. | H17: ▣ 유지보수 시 연계 시스템에 따른 이슈 발생 혹은 잠재적 리스크 발생 가능성 여부
B18: 7.1~9.0 : 높음 - 리스크가 크고 적극적인 관리 및 자원 투자가 필요. | H18: ▣ 외부 인력을 투입하여 상주 유지보수 필요 여부
B19: 9.1~10.0 : 매우 높음 - 높은 리스크와 복잡성으로 인해 프로젝트 성공에 큰 영향을 미침. | G19: 6. 사업 비용 및 검수 | H19: ▣ 프로젝트에 따른 추가 비용 발생 요소가 있는지 여부(사무실 임대, 장비 렌탈, 워크샵, 기타 비용)
H20: ▣ 프로젝트 검수를 방해할 수 있는 외부 요인이 있는지 여부(검수 절차, 아웃소싱 조직 여부, 협력사 등)

Sheet Sheet6
A1: 1. 기술적 난이도 체크 항목
A2: No | B2: 항목 | C2: 점수(1-10) | D2: 가중치 | E2: 결과 점수
A3: 1 | B3: 기술 스택 | C3: 10 | D3: 0.1 | E3: =C3*D3 -> 1
A4: 2 | B4: 아키텍처 | C4: 10 | D4: 0.1 | E4: =C4*D4 -> 1
A5: 3 | B5: 데이터 관리 | C5: 10 | D5: 0.1 | E5: =C5*D5 -> 1
A6: 4 | B6: 보안 | C6: 10 | D6: 0.1 | E6: =C6*D6 -> 1
A7: 5 | B7: 성능 | C7: 10 | D7: 0.1 | E7: =C7*D7 -> 1
A8: 6 | B8: 시스템 통합 | C8: 10 | D8: 0.1 | E8: =C8*D8 -> 1
A9: 7 | B9: 개발 도구 및 환경 | C9: 10 | D9: 0.1 | E9: =C9*D9 -> 1
A10: 8 | B10: 테스트 및 품질 보증 | C10: 10 | D10: 0.1 | E10: =C10*D10 -> 1
A11: 9 | B11: 배포 및 운영 | C11: 10 | D11: 0.1 | E11: =C11*D11 -> 1
A12: 10 | B12: 기술적 리스크 | C12: 10 | D12: 0.1 | E12: =C12*D12 -> 1
A13: 총합 | C13: =SUM(C3:C12) -> 100 | D13: =SUM(D3:D12) -> 1 | E13: =SUM(E3:E12) -> 10
A15: 2. 요구사항의 복잡성 체크 항목
A16: No | B16: 항목 | C16: 점수(1-10) | D16: 가중치 | E16: 결과 점수
A17: 1 | B17: 기능 및 범위 | C17: 10 | D17: 0.15 | E17: =C17*D17 -> 1.5
A18: 2 | B18: 요구사항의 명확성 | C18: 10 | D18: 0.15 | E18: =C18*D18 -> 1.5
A19: 3 | B19: 요구사항 변경 가능성 | C19: 10 | D19: 0.1 | E19: =C19*D19 -> 1
A20: 4 | B20: 사용자 및 사용 시나리오 | C20: 10 | D20: 0.1 | E20: =C20*D20 -> 1
A21: 5 | B21: 데이터 및 비즈니스 규칙 | C21: 10 | D21: 0.1 | E21: =C21*D21 -> 1
A22: 6 | B22: 성능 및 확장성 | C22: 10 | D22: 0.1 | E22: =C22*D22 -> 1
A23: 7 | B23: 보안 및 규정 준수 | C23: 10 | D23: 0.1 | E23: =C23*D23 -> 1
A24: 8 | B24: 외부 의존성 | C24: 10 | D24: 0.1 | E24: =C24*D24 -> 1
A25: 9 | B25: 우선순위 및 가치 | C25: 10 | D25: 0.1 | E25: =C25*D25 -> 1
A26: 총합 | C26: =SUM(C17:C25) -> 90 | D26: =SUM(D17:D25) -> 1 | E26: =SUM(E17:E25) -> 10
A28: 3. 프로젝트 팀 구성 난이도 체크 항목
A29: No | B29: 항목 | C29: 점수(1-10) | D29: 가중치 | E29: 결과 점수
A30: 1 | B30: 기술 숙련도 | C30: 4 | D30: 0.3 | E30: =C30*D30 -> 1.2
A31: 2 | B31: 도메인 지식 | C31: 3 | D31: 0.2 | E31: 0.45
A32: 3 | B32: 경험 | C32: 5 | D32: 0.2 | E32: 1
A33: 4 | B33: 인력 가용성 | C33: 2 | D33: 0.2 | E33: 0.4
A34: 5 | B34: 협업 능력 | C34: 4 | D34: 0.1 | E34: 0.4
A35: 총합 | C35: =SUM(C30:C34) -> 18 | D35: =SUM(D30:D34) -> 1 | E35: =SUM(E30:E34) -> 3.45
A37: 4. 프로젝트 관리 난이도 체크 항목
A38: No | B38: 항목 | C38: 점수(1-10) | D38: 가중치 | E38: 결과 점수
A39: 1 | B39: 일정 관리 | C39: 4 | D39: 0.2 | E39: =C39*D39 -> 0.8
A40: 2 | B40: 리소스 관리 | C40: 5 | D40: 0.15 | E40: =C40*D40 -> 0.75
A41: 3 | B41: 리스크 관리 | C41: 4 | D41: 0.1 | E41: =C41*D41 -> 0.4
A42: 4 | B42: 이해관계자 관리 | C42: 2 | D42: 0.1 | E42: =C42*D42 -> 0.2
A43: 5 | B43: 품질 관리 | C43: 3 | D43: 0.1 | E43: =C43*D43 -> 0.3
...
